<?xml version='1.0'?>
<sdf version='1.4'>
	<model name="hector">

		<static>false</static>

		<link name='base_link'>
			<inertial>
				<mass>3</mass>
				<inertia>
					<ixx>0.006</ixx>
					<ixy>0.0</ixy>
					<ixz>0.0</ixz>
					<iyy>0.006</iyy>
					<iyz>0.0</iyz>
					<izz>0.006</izz>
				</inertia>
			</inertial>
			<collision name='base_link_collision'>
				<pose>0 0 0.03 0 0 0</pose>
				<geometry>
					<box>
						<size>0.26 0.205 0.18</size>
					</box>
				</geometry>
			</collision>

			<visual name='base_link_visual'>
				<pose>0 0 -0.06 0 0 0</pose>
				<geometry>
					<mesh>
						<uri>model://swarmie/meshes/Body.stl</uri>
					</mesh>
				</geometry>
				<material>
					<script>
						<name>Gazebo/Grey</name>
					</script>
				</material>
			</visual>

			<sensor type="ray" name="us_left_sensor">
				<pose>0.15 0.07 0.053 0.0 0.0 0.43633</pose>
				<visualize>false</visualize>
				<update_rate>5</update_rate>
				<ray>
					<scan>
						<horizontal>
							<samples>3</samples>
							<resolution>1.0</resolution>
							<min_angle>-.478</min_angle>
							<max_angle>0.478</max_angle>
						</horizontal>
					</scan>
					<range>
						<min>0.010</min>
						<max>3</max>
						<resolution>0.01</resolution>
					</range>
				</ray>
				<plugin name="us" filename="libhector_gazebo_ros_sonar.so">
					<gaussianNoise>0.005</gaussianNoise>
					<topicName>/hector/sonarLeft</topicName>
					<frameId>us_center_link</frameId>
				</plugin>
			</sensor>
			<sensor type="ray" name="us_right_sensor">
				<pose>0.15 -0.07 0.053 0.0 0.0 -0.43633</pose>
				<visualize>false</visualize>
				<update_rate>5</update_rate>
				<ray>
					<scan>
						<horizontal>
							<samples>3</samples>
							<resolution>1.0</resolution>
							<min_angle>-.478</min_angle>
							<max_angle>0.478</max_angle>
						</horizontal>
					</scan>
					<range>
						<min>0.010</min>
						<max>3</max>
						<resolution>0.01</resolution>
					</range>
				</ray>
				<plugin name="us" filename="libhector_gazebo_ros_sonar.so">
					<gaussianNoise>0.005</gaussianNoise>
					<topicName>/hector/sonarRight</topicName>
					<frameId>us_center_link</frameId>
				</plugin>
			</sensor>
			<sensor type="ray" name="us_center_sensor">
				<pose>0.15 0 0.053 0 0 0</pose>
				<visualize>false</visualize>
				<update_rate>5</update_rate>
				<ray>
					<scan>3.0
						<horizontal>
							<samples>3</samples>
							<resolution>1.0</resolution>
							<min_angle>-.478</min_angle>
							<max_angle>0.478</max_angle>
						</horizontal>
					</scan>
					<range>
						<min>0.010</min>
						<max>3</max>
						<resolution>0.01</resolution>
					</range>
				</ray>
				<plugin name="us" filename="libhector_gazebo_ros_sonar.so">
					<gaussianNoise>0.005</gaussianNoise>
					<topicName>/hector/sonarCenter</topicName>
					<frameId>us_center_link</frameId>
				</plugin>
			</sensor>
			<sensor type="camera" name="camera">
				<pose>0.145 -0.0162 0.088 0.0 0.628 0.0</pose>
				<visualize>false</visualize>
				<update_rate>6.0</update_rate>
				<camera name="head">
					<horizontal_fov>1.0123</horizontal_fov>
					<image>
						<width>320</width>
						<height>240</height>
						<format>B8G8R8</format>
					</image>
					<clip>
						<near>0.02</near>
						<far>300</far>
					</clip>
					<noise>
						<type>gaussian</type>
						<mean>0.0</mean>
						<stddev>0.007</stddev>
					</noise>
				</camera>
				<plugin name="camera_controller" filename="libgazebo_ros_camera.so">
					<alwaysOn>true</alwaysOn>
					<updateRate>0.0</updateRate>
					<cameraName>/hector/camera</cameraName>
					<imageTopicName>/hector/camera/image</imageTopicName>
					<cameraInfoTopicName>/hector/camera/info</cameraInfoTopicName>
					<frameName>camera_link</frameName>
					<hackBaseline>0.1</hackBaseline>
					<distortionK1>0.0</distortionK1>
					<distortionK2>0.0</distortionK2>
					<distortionK3>0.0</distortionK3>
					<distortionT1>0.0</distortionT1>
					<distortionT2>0.0</distortionT2>
					<CxPrime>0.0</CxPrime>
					<Cx>0.0</Cx>
					<Cy>0.0</Cy>
					<focalLength>0.0</focalLength>
				</plugin>
			</sensor>

			<collision name='top_plate_collision'>
				<pose>0 0 0.12 0 0 0</pose>
				<geometry>
					<box>
						<size>0.25 0.30 0.005</size>
					</box>
				</geometry>
			</collision>
			<visual name='top_plate_visual'>
				<pose>0.0006 0 0.12 0 0 0</pose>
				<geometry>
					<mesh>
						<uri>model://swarmie/meshes/CoverPlate.stl</uri>
					</mesh>
				</geometry>
				<material>
					<script>
						<name>Gazebo/Blue</name>
					</script>
				</material>
			</visual>

			<collision name='cow_catcher_front_left_collision'>
				<pose>0.1675 0.06 -0.05 0 -0.4 0.3</pose>
				<geometry>
					<box>
					  <size>0.01 0.08 0.06</size>
					</box>
				</geometry>
			</collision>
      
			<collision name='wheel_guard_front_left_collision'>
				<pose>0.148 0.13 -0.05 0 0 0</pose>
				<geometry>
					<box>
					  <size>0.01 0.08 0.06</size>
					</box>
				</geometry>
			</collision>

			<collision name='cow_catcher_front_right_collision'>
				<pose>0.1675 -0.06 -0.05 0 -0.4 -0.3</pose>
				<geometry>
					<box>
					  <size>0.01 0.08 0.06</size>
					</box>
				</geometry>
			</collision>
      
			<collision name='wheel_guard_front_right_collision'>
				<pose>0.148 -0.13 -0.05 0 0 0</pose>
				<geometry>
					<box>
					  <size>0.01 0.08 0.06</size>
					</box>
				</geometry>
			</collision>
      
			<visual name='cow_catcher_front_visual'>
				<pose>0.1675 0 -0.08 1.57079 0 0</pose>
				<geometry>
					<mesh>
						<uri>model://swarmie/meshes/CowCatcherFront.stl</uri>
						<scale>0.001 0.001 0.001</scale>
					</mesh>
				</geometry>
				<material>
					<script>
						<name>Gazebo/FlatBlack</name>
					</script>
				</material>
			</visual>

			<collision name='cow_catcher_back_lower_collision'>
				<pose>-0.1305 0.0 -0.0665 1.57079 1.05 0.0</pose>
				<geometry>
					<box>
					  <size>0.01 0.03 0.18</size>
					</box>
				</geometry>
			</collision>
			<visual name='cow_catcher_back_visual'>
				<pose>-0.1275 -0.1 -0.04 1.57079 0 3.1415</pose>
				<geometry>
					<mesh>
						<uri>model://swarmie/meshes/CowCatcherRear.stl</uri>
						<scale>0.001 0.001 0.001</scale>
					</mesh>
				</geometry>
				<material>
					<script>
						<name>Gazebo/FlatBlack</name>
					</script>
				</material>
			</visual>

		</link>

	<link name="gripper_wrist">
			<pose>0.155 0 -0.013 0 0 0</pose>
			<inertial>
				<mass>0.03</mass>
				<inertia> 
					<ixx>0.00245</ixx> <!--> 1/12*(mass)(h^2 + d^2) where h,d,w are in meters and mass is in kilograms <-->
					<ixy>0.0</ixy>
					<ixz>0.0</ixz>
					<iyy>0.00185</iyy> <!--> 1/12*(mass)(w^2 + d^2) <-->
					<iyz>0.0</iyz>
					<izz>0.00185</izz> <!--> 1/12*(mass)(w^2 + h^2) <-->
				</inertia>
			</inertial>

			<visual name="visual">
				<pose>0 0 0 0 0 0</pose>
				<geometry>
					<mesh>
						<uri>model://swarmie/meshes/GripperWrist.stl</uri>
					</mesh>
				</geometry>
				<material>
					<script>
						<name>Gazebo/Grey</name>
					</script>
				</material>
			</visual>
			<collision name="collision">
			  <pose>0.0 0 -0.0055 0 0 0</pose>
				<geometry>
					<box>
					  <size>0.07 0.05 0.07</size>
					</box>
				</geometry>
			</collision>
		</link>

		<joint name="gripper_wrist_joint" type="revolute">
			<parent>base_link</parent>
			<child>gripper_wrist</child>
			<pose>-0.0227 0 -0.0105 0 0 0</pose>
			<axis>
				<xyz>0 1 0</xyz>
				<limit>
					<upper>0.7</upper>
					<lower>0.0</lower>
				</limit>
				<dynamics>
				  <damping>0.5</damping>
				</dynamics>
			</axis>
		</joint>

		<link name="gripper_left_finger">
			<pose>0.214 0.016 0.0095 0 0 0</pose>
			<inertial>
				<mass>0.005</mass>
				<inertia>
					<ixx>0.0000833</ixx>
					<ixy>0.0</ixy>
					<ixz>0.0</ixz>
					<iyy>0.0005417</iyy>
					<iyz>0.0</iyz>
					<izz>0.0006083</izz>
				</inertia>
			</inertial>
			<collision name="collision">
				<pose>0 0 0 0 0 -0.38</pose>
				<geometry>
					<box>
						<size>0.06 0.01 0.007</size>
					</box>
				</geometry>
				<surface>
					<friction>
						<ode>
							<mu>0.8</mu>
							<mu2>0.7</mu2>
						</ode>
					</friction>
				</surface>
			</collision>
			<collision name="collision2">
				<pose>0.033 -0.014 0.000 0 0 -0.38</pose>
				<geometry>
					<box>
						<size>0.01 0.01 0.007</size>
					</box>
				</geometry>
				<surface>
					<friction>
						<ode>
							<mu>0.8</mu>
							<mu2>0.7</mu2>
						</ode>
					</friction>
				</surface>
			</collision>
			<visual name="visual">
				<pose>0 0 0 0 0 0.0</pose>
				<geometry>
					<mesh>
						<uri>model://swarmie/meshes/GripperFingerLeft.stl</uri>
					</mesh>
				</geometry>
				<material>
					<script>
						<name>Gazebo/Grey</name>
					</script>
				</material>
			</visual>
			<sensor name='finger' type='contact'>
			  <contact>
			    <collision>collision</collision>
			  </contact>
			</sensor>
		</link>

		<joint name ="gripper_left_finger_joint" type="revolute">
			<parent>gripper_wrist</parent>
			<child>gripper_left_finger</child>
			<pose>-0.0324 0.0052 0 0 0 0</pose>
			<axis>
				<xyz>0 0 1</xyz>
				<limit>
					<upper>0.7854</upper>
					<lower>0.0</lower>
				</limit>
				<dynamics>
				  <damping>0.3</damping>
				</dynamics>
			</axis>
		</joint>

		<link name="gripper_right_finger">
			<pose>0.214 -0.016 0.0095 0 0 0</pose>
			<inertial>
 				<mass>0.005</mass>
				<inertia>
					<ixx>0.0000833</ixx>
					<ixy>0.0</ixy>
					<ixz>0.0</ixz>
					<iyy>0.0005417</iyy>
					<iyz>0.0</iyz>
					<izz>0.0006083</izz>
				</inertia>
			</inertial>
			<collision name="collision">
				<pose>0 0 0 0 0 0.38</pose>
				<geometry>
					<box>
						<size>0.06 0.01 0.007</size>
					</box>
				</geometry>
				<surface>
					<friction>
						<ode>
							<mu>0.8</mu>
							<mu2>0.7</mu2>
						</ode>
					</friction>
				</surface>
			</collision>
			<collision name="collision2">
				<pose>0.033 0.014 0.000 0 0 0.38</pose>
				<geometry>
					<box>
						<size>0.01 0.01 0.007</size>
					</box>
				</geometry>
				<surface>
					<friction>
						<ode>
							<mu>0.8</mu>
							<mu2>0.7</mu2>
						</ode>
					</friction>
				</surface>
			</collision>
			<visual name="visual">3.0
				<pose>0 0 0 0 0 0</pose>
				<geometry>
					<mesh>
						<uri>model://swarmie/meshes/GripperFingerRight.stl</uri>
					</mesh>
				</geometry>
				<material>
					<script>
						<name>Gazebo/Grey</name>
					</script>
				</material>
			</visual>
			<sensor name='finger' type='contact'>
			  <contact>
			    <collision>collision</collision>
			  </contact>
			</sensor>
		</link>

		<joint name ="gripper_right_finger_joint" type="revolute">
			<parent>gripper_wrist</parent>
			<child>gripper_right_finger</child>
			<pose>-0.0324 -0.0052 0 0 0 0</pose>
			<axis>
				<xyz>0 0 1</xyz>
				<limit>
					<upper>0.0</upper>
					<lower>-0.7854</lower>
				</limit>
				<dynamics>
				  <damping>0.3</damping>
				</dynamics>
			</axis>
		</joint>

		<link name="left_front_wheel">
			<pose>0.095 0.135 -0.03 0 0 0</pose>
			<inertial>
				<mass>1.0</mass>
				<inertia>
					<ixx>0.000776</ixx>
					<ixy>0.0</ixy>
					<ixz>0.0</ixz>
					<iyy>0.0012</iyy>
					<iyz>0.0</iyz>
					<izz>0.000776</izz>
				</inertia>
			</inertial>
			<collision name="collision">
				<pose>0 0 0 1.5708 0 0</pose>
				<geometry>
					<cylinder>
						<radius>.0575</radius>
						<length>.07</length>
 					</cylinder>
				</geometry>
				<surface>
					<friction>
						<ode>
							<mu>0.8</mu>
							<mu2>0.7</mu2>
						</ode>
					</friction>
				</surface>
			</collision>
			<visual name="visual">
				<geometry>
					<mesh>
						<uri>model://swarmie/meshes/TireWheelLeft.stl</uri>
					</mesh>
				</geometry>
				<material>
					<script>
						<name>Gazebo/Grey</name>
					</script>
				</material>
			</visual>
		</link>

		<joint name="left_front" type="revolute">
			<parent>base_link</parent>
			<child>left_front_wheel</child>
			<axis>
				<xyz>0 1 0</xyz>
			</axis>
		</joint>

		<link name="right_front_wheel">base_link
			<pose>0.095 -0.135 -0.03 0 0 0</pose>
			<inertial>
				<mass>1.0</mass>
				<inertia>
         <ixx>0.000776</ixx>
         <ixy>0.0</ixy>
         <ixz>0.0</ixz>
         <iyy>0.0012</iyy>
         <iyz>0.0</iyz>
         <izz>0.000776</izz>
				</inertia>
			</inertial>
			<collision name="collision">
				<pose>0 0 0 -1.5708 0 0</pose>
				<geometry>
					<cylinder>
						<radius>.0575</radius>
						<length>.07</length>
					</cylinder>
				</geometry>
				<surface>
					<friction>
						<ode>
							<mu>0.8</mu>
							<mu2>0.7</mu2>
						</ode>
					</friction>
				</surface>
			</collision>
			<visual name="visual">
				<geometry>
					<mesh>
						<uri>model://swarmie/meshes/TireWheelRight.stl</uri>
					</mesh>
				</geometry>
				<material>
					<script>
						<name>Gazebo/Grey</name>
					</script>
				</material>
			</visual>
		</link>

		<joint name="right_front" type="revolute">
			<parent>base_link</parent>
			<child>right_front_wheel</child>
			<axis>
				<xyz>0 1 0</xyz>
			</axis>
		</joint>

		<link name="left_rear_wheel">
			<pose>-0.095 0.135 -0.03 0 0 0</pose>
			<inertial>
				<mass>1.0</mass>
				<inertia>
         <ixx>0.000776</ixx>
         <ixy>0.0</ixy>
         <ixz>0.0</ixz>
         <iyy>0.0012</iyy>
         <iyz>0.0</iyz>
         <izz>0.000776</izz>
				</inertia>
			</inertial>
			<collision name="collision">
				<pose>0 0 0 1.5708 0 0</pose>
				<geometry>
					<cylinder>
						<radius>.0575</radius>
						<length>.065</length>
					</cylinder>
				</geometry>
				<surface>
					<friction>
						<ode>
							<mu>0.8</mu>
							<mu2>0.7</mu2>
						</ode>
					</friction>
				</surface>
			</collision>
			<visual name="visual">
				<geometry>
					<mesh>
						<uri>model://swarmie/meshes/TireWheelLeft.stl</uri>
					</mesh>
				</geometry>
				<material>
					<script>
						<name>Gazebo/Grey</name>
					</script>
				</material>
			</visual>
		</link>

		<joint name="left_rear" type="revolute">
			<parent>base_link</parent>
			<child>left_rear_wheel</child>
			<axis>
				<xyz>0 1 0</xyz>
			</axis>
		</joint>

		<link name="right_rear_wheel">
			<pose>-0.095 -0.135 -0.03 0 0 0</pose>
			<inertial>
				<mass>1.0</mass>
				<inertia>
         <ixx>0.000776</ixx>
         <ixy>0.0</ixy>
         <ixz>0.0</ixz>
         <iyy>0.0012</iyy>
         <iyz>0.0</iyz>
         <izz>0.000776</izz>
				</inertia>
			</inertial>
			<collision name="collision">
				<pose>0 0 0 -1.5708 0 0</pose>
				<geometry>
					<cylinder>
						<radius>.0575</radius>
						<length>.07</length>
					</cylinder>
				</geometry>
				<surface>
					<friction>
						<ode>
							<mu>0.8</mu>
							<mu2>0.7</mu2>
						</ode>
					</friction>
				</surface>
			</collision>
			<visual name="visual">
				<geometry>
					<mesh>
						<uri>model://swarmie/meshes/TireWheelRight.stl</uri>
					</mesh>
				</geometry>
				<material>
					<script>
						<name>Gazebo/Grey</name>
					</script>
				</material>
			</visual>
		</link>

		<joint name="right_rear" type="revolute">
			<parent>base_link</parent>
			<child>right_rear_wheel</child>
			<axis>
				<xyz>0 1 0</xyz>
			</axis>
		</joint>   

		<!-- Gripper plugin-->
		<plugin name="gripper_sim" filename="libgazebo_plugins_gripper.so">
			<!-- required: joint definitions -->
			<wristJoint>gripper_wrist_joint</wristJoint>
			<leftFingerJoint>gripper_left_finger_joint</leftFingerJoint>
			<rightFingerJoint>gripper_right_finger_joint</rightFingerJoint>

			<!-- required: data input topics for this plugin -->
			<wristTopic>/hector/wristAngle/cmd</wristTopic>
			<fingerTopic>/hector/fingerAngle/cmd</fingerTopic>

			<!-- optional: print debug info to the console -->
			<debug>
				<!-- true (debug mode is on) or false (debug mode is off) -->
				<printToConsole>false</printToConsole>
				<!-- time (in simulated seconds) between debug print statements -->
				<printDelayInSeconds>5.0</printDelayInSeconds>
			</debug>

			<!-- optional: the refresh rate of the gripper and all debugging output -->
			<!-- this value is the number of updates performed per second -->
			<!-- warning: low values (i.e. < 100) can cause the gripper to have poor performance -->
			<updateRate>1000.0</updateRate>

			<!-- optional: set the default PID values for the wrist joint -->
			<!-- values in order: Proportional gain, Integral gain, Derivative gain -->
      <wristPID>1.0 0.0 0.0</wristPID>

			<!-- optional: set the default PID values for the finger joints -->
			<!-- values in order: Proportional gain, Integral gain, Derivative gain -->
			<!-- it is always assumed that both fingers use the same PID values -->
      <fingerPID>1.0 0.0 0.0</fingerPID>

			<!-- optional: set the min/max force applicable to the wrist joint in Newtons -->
			<!-- values in order: minimum force, maximum force -->
      <wristForceLimits>-0.5 0.5</wristForceLimits>

			<!-- optional: set the min/max force applicable to the finger joints in Newtons -->
			<!-- values in order: minimum force, maximum force -->
			<!-- it is always assumed that both fingers use the same min/max force values -->
      <fingerForceLimits>-0.5 0.5</fingerForceLimits>
		</plugin>

		<!-- Skid Steer Drive plugin -->
		<plugin name="skid_steer_drive_controller" filename="libgazebo_ros_skid_steer_drive.so">
			<updateRate>10</updateRate>
			<robotNamespace>/</robotNamespace>
			<leftFrontJoint>left_front</leftFrontJoint>
			<rightFrontJoint>right_front</rightFrontJoint>
			<leftRearJoint>left_rear</leftRearJoint>
			<rightRearJoint>right_rear</rightRearJoint>
			<wheelSeparation>0.27</wheelSeparation>
			<wheelDiameter>0.12</wheelDiameter>
			<robotBaseFrame>hector/base_link</robotBaseFrame>
			<torque>2.8</torque>
			<commandTopic>/hector/skidsteer</commandTopic>
			<odometryTopic>/hector/odom</odometryTopic>
			<odometryFrame>hector/odom</odometryFrame>
			<broadcastTF>0</broadcastTF>base_link
		</plugin>

		<!-- GPS plugin -->
		<plugin name="gps_sim" filename="libhector_gazebo_ros_gps.so">
			<alwaysOn>1</alwaysOn>
			<updateRate>5</updateRate>
			<bodyName>base_link</bodyName>
			<frameId>hector/base_link</frameId>
			<topicName>/hector/fix</topicName>
			<referenceLatitude>28.584810</referenceLatitude>
			<referenceLongitude>-80.649650</referenceLongitude>
			<referenceHeading>0.0</referenceHeading>
			<referenceAltitude>10.0</referenceAltitude>
			<offset>0.0 0.0 0.0</offset>
			<drift>0.1 0.1 0</drift>
			<driftFrequency>0.0 0.0 0.0</driftFrequency>
			<gaussianNoise>0.4 0.5 0.0</gaussianNoise>
		</plugin>

		<!-- IMU plugin -->
		<plugin name="imu_sim" filename="libhector_gazebo_ros_imu.so">
			<updateRate>10</updateRate>
			<bodyName>base_link</bodyName>
			<frameId>hector/base_link</frameId>
			<topicName>/hector/imu</topicName>
			<xyzOffset>0 0 0</xyzOffset>
			<rpyOffset>0 0 0</rpyOffset>
			<gaussianNoise>0</gaussianNoise>  
			<accelDrift>0.5 0.5 0.5</accelDrift>
			<accelGaussianNoise>0.35 0.35 0.3</accelGaussianNoise>
			<rateDrift>0.1 0.1 0.1</rateDrift>
			<rateGaussianNoise>0.05 0.05 0.015</rateGaussianNoise>
			<headingDrift>0.01</headingDrift>
			<headingGaussianNoise>0.01</headingGaussianNoise>
		</plugin>

	</model>
</sdf>
