<?xml version="1.0" ?>
<sdf version="1.4">
  <model name="RASSOR2">

    <link name="chassis">
      <pose>0 0 0.240 0 0 0</pose>
      <inertial>
        <mass>35</mass>
        <inertia>
          <ixx>0.33</ixx>
          <ixy>0.0</ixy>
          <ixz>0.0</ixz>
          <iyy>6.7</iyy>
          <iyz>0.0</iyz>
          <izz>1.3</izz>
        </inertia>
      </inertial>
      <collision name="chassis_collision">
        <geometry>
	  <box>
	    <size>.60 .30 .15</size>
	  </box>
        </geometry>
	<surface>
	  <friction>
	    <ode>
	      <mu>0.9</mu>
	      <mu2>0.9</mu2>
	      <fdir1>0 0 0</fdir1>
	      <slip1>0.01</slip1>
	      <slip2>0.01</slip2>
	    </ode>
	  </friction>
	</surface>
      </collision>
      <visual name="chassis_visual">
        <geometry>
	  <!-- <box>
	    <size>.60 .30 .15</size>
	  </box> -->
          <mesh>
            <uri>model://rassor2/chassis.dae</uri>
            <scale>1.0 1.0 1.0</scale>
          </mesh>
        </geometry>
	<material>
	    <ambient>0.8 0.2 0.2 1</ambient>
	    <diffuse>0.8 0.2 0.2 1</diffuse>
	    <specular>0.1 0.1 0.1 1</specular>
	    <emissive>0 0 0 0</emissive>
	</material>
      </visual>
    </link> <!-- end of chassis link -->




       <link name="front_arm_link">
            <pose>0.205 0.005 0.245 0 0 0</pose>
	    <inertial>
		<mass>2</mass>
		<inertia>
		  <ixx>0.04</ixx>
		  <ixy>0.0</ixy>
		  <ixz>0.0</ixz>
		  <iyy>0.04</iyy>
		  <iyz>0.0</iyz>
		  <izz>0.004</izz>
		</inertia>
	    </inertial>
            <collision name="collision">
            <pose>0 0 0.350 0 0 0</pose>
	      <geometry>
		<cylinder>
		  <radius>0.060</radius>
		  <length>0.4</length>
		</cylinder>
	      </geometry>
		<surface>
		  <friction>
		    <ode>
		      <mu>0.9</mu>
		      <mu2>0.9</mu2>
		      <fdir1>0 0 0</fdir1>
		      <slip1>0.01</slip1>
		      <slip2>0.01</slip2>
		    </ode>
		  </friction>
		</surface>
            </collision>
            <visual name="visual">
            <pose>0 -0.002 0.275 0 0 0</pose>
                <geometry>
		<!-- <cylinder>
		  <radius>0.060</radius>
		  <length>0.4</length>
		</cylinder> -->
                    <mesh>
            		<uri>model://rassor2/arm.dae</uri>
	                <scale>1.0 1.0 1.0</scale>
                    </mesh>
                </geometry>
		<material>
		    <ambient>0.3 0.3 0.3 1</ambient>
		    <diffuse>0.3 0.3 0.3 1</diffuse>
		    <specular>0.1 0.1 0.1 1</specular>
		    <emissive>0 0 0 0</emissive>
		</material>
            </visual>
        </link>
        
        <joint name="front_arm" type="revolute">
            <parent>chassis</parent>
            <child>front_arm_link</child>
            <axis>
                <xyz>0 1 0</xyz>
	        <limit>
	          <upper>3.82</upper>
	          <lower>-0.7</lower>
	        </limit>
            </axis>
        </joint>


      <link name="front_right_drum_link">
            <pose>0.205 -0.265 0.8 1.5708 0 0</pose>
	    <inertial>
		<mass>12</mass>
		<inertia>
		  <ixx>0.077</ixx>
		  <ixy>0.0</ixy>
		  <ixz>0.0</ixz>
		  <iyy>0.077</iyy>
		  <iyz>0.0</iyz>
		  <izz>0.093</izz>
		</inertia>
	    </inertial>
            <collision name="collision">
	      <geometry>
		<cylinder>
		  <radius>0.2159</radius>
		  <length>0.370</length>
		</cylinder>
	      </geometry>
		<surface>
		  <friction>
		    <ode>
		      <mu>0.9</mu>
		      <mu2>0.9</mu2>
		      <fdir1>0 0 0</fdir1>
		      <slip1>0.1</slip1>
		      <slip2>0.1</slip2>
		    </ode>
		  </friction>
		</surface>
            </collision>
            <visual name="visual">
                <geometry>
		<!-- <cylinder>
		  <radius>0.2159</radius>
		  <length>0.370</length>
		</cylinder> -->
                    <mesh>
            		<uri>model://rassor2/right-drum.dae</uri>
	                <scale>1.0 1.0 1.0</scale>
                    </mesh>
                </geometry>
		<!-- <material>
		  <script>
		    <uri>model://media/materials/scripts</uri>
		    <uri>model://media/materials/textures</uri>
		    <name>Tile/Diffuse</name>
		  </script>
		</material> -->
		<material>
		    <ambient>0.6 0.6 0.63 1</ambient>
		    <diffuse>0.6 0.6 0.63 1</diffuse>
		    <specular>0.1 0.1 0.1 1</specular>
		    <emissive>0 0 0 0</emissive>
		</material>
            </visual>
        </link>
        
        <joint name="front_right_drum" type="revolute">
            <parent>front_arm_link</parent>
            <child>front_right_drum_link</child>
            <axis>
                <xyz>0 1 0</xyz>
            </axis>
        </joint>




       <link name="front_left_drum_link">
            <pose>0.205 0.265 0.8 1.5708 0 0</pose>
	    <inertial>
		<mass>12</mass>
		<inertia>
		  <ixx>0.077</ixx>
		  <ixy>0.0</ixy>
		  <ixz>0.0</ixz>
		  <iyy>0.077</iyy>
		  <iyz>0.0</iyz>
		  <izz>0.093</izz>
		</inertia>
	    </inertial>
            <collision name="collision">
	      <geometry>
		<cylinder>
		  <radius>0.2159</radius>
		  <length>0.370</length>
		</cylinder>
	      </geometry>
		<surface>
		  <friction>
		    <ode>
		      <mu>0.9</mu>
		      <mu2>0.9</mu2>
		      <fdir1>0 0 0</fdir1>
		      <slip1>0.1</slip1>
		      <slip2>0.1</slip2>
		    </ode>
		  </friction>
		</surface>
            </collision>
            <visual name="visual">
            <pose>0 0 0 3.1416 0 0</pose>
                <geometry>
		<!-- <cylinder>
		  <radius>0.2159</radius>
		  <length>0.370</length>
		</cylinder> -->
                    <mesh>
            		<uri>model://rassor2/left-drum.dae</uri>
	                <scale>1.0 1.0 1.0</scale>
                    </mesh>
                </geometry>
		<!-- <material>
		  <script>
		    <uri>model://media/materials/scripts</uri>
		    <uri>model://media/materials/textures</uri>
		    <name>Tile/Diffuse</name>
		  </script>
		</material> -->
		<material>
		    <ambient>0.6 0.6 0.63 1</ambient>
		    <diffuse>0.6 0.6 0.63 1</diffuse>
		    <specular>0.1 0.1 0.1 1</specular>
		    <emissive>0 0 0 0</emissive>
		</material>
            </visual>
        </link>
        
        <joint name="front_left_drum" type="revolute">
            <parent>front_arm_link</parent>
            <child>front_left_drum_link</child>
            <axis>
                <xyz>0 1 0</xyz>
            </axis>
        </joint>




       <link name="rear_arm_link">
            <pose>-0.205 0.005 0.245 0 0 0</pose>
	    <inertial>
		<mass>2</mass>
		<inertia>
		  <ixx>0.04</ixx>
		  <ixy>0.0</ixy>
		  <ixz>0.0</ixz>
		  <iyy>0.04</iyy>
		  <iyz>0.0</iyz>
		  <izz>0.004</izz>
		</inertia>
	    </inertial>
            <collision name="collision">
            <pose>0 0 0.350 0 0 0</pose>
	      <geometry>
		<cylinder>
		  <radius>0.060</radius>
		  <length>0.4</length>
		</cylinder>
	      </geometry>
		<surface>
		  <friction>
		    <ode>
		      <mu>0.9</mu>
		      <mu2>0.9</mu2>
		      <fdir1>0 0 0</fdir1>
		      <slip1>0.01</slip1>
		      <slip2>0.01</slip2>
		    </ode>
		  </friction>
		</surface>
            </collision>
            <visual name="visual">
            <pose>0 -0.002 0.275 0 0 0</pose>
                <geometry>
		<!-- <cylinder>
		  <radius>0.060</radius>
		  <length>0.4</length>
		</cylinder> -->
                    <mesh>
            		<uri>model://rassor2/arm.dae</uri>
	                <scale>1.0 1.0 1.0</scale>
                    </mesh>
                </geometry>
		<material>
		    <ambient>0.3 0.3 0.3 1</ambient>
		    <diffuse>0.3 0.3 0.3 1</diffuse>
		    <specular>0.1 0.1 0.1 1</specular>
		    <emissive>0 0 0 0</emissive>
		</material>
            </visual>
        </link>
        
        <joint name="rear_arm" type="revolute">
            <parent>chassis</parent>
            <child>rear_arm_link</child>
            <axis>
                <xyz>0 1 0</xyz>
	        <limit>
	          <upper>0.7</upper>
	          <lower>-3.82</lower>
	        </limit>
            </axis>
        </joint>




       <link name="rear_right_drum_link">
            <pose>-0.205 -0.265 0.8 1.5708 0 0</pose>
	    <inertial>
		<mass>4</mass>
		<inertia>
		  <ixx>0.077</ixx>
		  <ixy>0.0</ixy>
		  <ixz>0.0</ixz>
		  <iyy>0.077</iyy>
		  <iyz>0.0</iyz>
		  <izz>0.093</izz>
		</inertia>
	    </inertial>
            <collision name="collision">
	      <geometry>
		<cylinder>
		  <radius>0.2159</radius>
		  <length>0.370</length>
		</cylinder>
	      </geometry>
		<surface>
		  <friction>
		    <ode>
		      <mu>0.9</mu>
		      <mu2>0.9</mu2>
		      <fdir1>0 0 0</fdir1>
		      <slip1>0.1</slip1>
		      <slip2>0.1</slip2>
		    </ode>
		  </friction>
		</surface>
            </collision>
            <visual name="visual">
                <geometry>
		<!-- <cylinder>
		  <radius>0.2159</radius>
		  <length>0.370</length>
		</cylinder> -->
                    <mesh>
            		<uri>model://rassor2/left-drum.dae</uri>
	                <scale>1.0 1.0 1.0</scale>
                    </mesh>
                </geometry>
		<!-- <material>
		  <script>
		    <uri>model://media/materials/scripts</uri>
		    <uri>model://media/materials/textures</uri>
		    <name>Tile/Diffuse</name>
		  </script>
		</material> -->
		<material>
		    <ambient>0.6 0.6 0.63 1</ambient>
		    <diffuse>0.6 0.6 0.63 1</diffuse>
		    <specular>0.1 0.1 0.1 1</specular>
		    <emissive>0 0 0 0</emissive>
		</material>
            </visual>
        </link>
        
        <joint name="rear_right_drum" type="revolute">
            <parent>rear_arm_link</parent>
            <child>rear_right_drum_link</child>
            <axis>
                <xyz>0 1 0</xyz>
            </axis>
        </joint>




       <link name="rear_left_drum_link">
            <pose>-0.205 0.265 0.8 1.5708 0 0</pose>
	    <inertial>
		<mass>4</mass>
		<inertia>
		  <ixx>0.077</ixx>
		  <ixy>0.0</ixy>
		  <ixz>0.0</ixz>
		  <iyy>0.077</iyy>
		  <iyz>0.0</iyz>
		  <izz>0.093</izz>
		</inertia>
	    </inertial>
            <collision name="collision">
	      <geometry>
		<cylinder>
		  <radius>0.2159</radius>
		  <length>0.304</length>
		</cylinder>
	      </geometry>
		<surface>
		  <friction>
		    <ode>
		      <mu>0.9</mu>
		      <mu2>0.9</mu2>
		      <fdir1>0 0 0</fdir1>
		      <slip1>0.1</slip1>
		      <slip2>0.1</slip2>
		    </ode>
		  </friction>
		</surface>
            </collision>
            <visual name="visual">
            <pose>0 0 0 3.1416 0 0</pose>
                <geometry>
		<!-- <cylinder>
		  <radius>0.2159</radius>
		  <length>0.304</length>
		</cylinder> -->
                    <mesh>
            		<uri>model://rassor2/right-drum.dae</uri>
	                <scale>1.0 1.0 1.0</scale>
                    </mesh>
                </geometry>
		<!-- <material>
		  <script>
		    <uri>model://media/materials/scripts</uri>
		    <uri>model://media/materials/textures</uri>
		    <name>Tile/Diffuse</name>
		  </script>
		</material> -->
		<material>
		    <ambient>0.6 0.6 0.63 1</ambient>
		    <diffuse>0.6 0.6 0.63 1</diffuse>
		    <specular>0.1 0.1 0.1 1</specular>
		    <emissive>0 0 0 0</emissive>
		</material>
           </visual>
        </link>
        
        <joint name="rear_left_drum" type="revolute">
            <parent>rear_arm_link</parent>
            <child>rear_left_drum_link</child>
            <axis>
                <xyz>0 1 0</xyz>
            </axis>
        </joint>



        <link name="left_front_wheel">
            <pose>0.250 0.240 0.2159 -1.5708 0 0</pose>
	    <inertial>
		<mass>4</mass>
		<inertia>
		  <ixx>0.05</ixx>
		  <ixy>0.0</ixy>
		  <ixz>0.0</ixz>
		  <iyy>0.05</iyy>
		  <iyz>0.0</iyz>
		  <izz>0.09</izz>
		</inertia>
	    </inertial>
            <collision name="collision">
	      <geometry>
		<cylinder>
		  <radius>0.2159</radius><!-- 6 in wide, 17 inch diameter-->
		  <length>0.1524</length>
		</cylinder>
	      </geometry>
		<surface>
		  <friction>
		    <ode>
		      <mu>0.9</mu>
		      <mu2>0.9</mu2>
		      <fdir1>0 0 0</fdir1>
		      <slip1>0.8</slip1>
		      <slip2>0.4</slip2>
		    </ode>
		  </friction>
		</surface>
            </collision>
            <visual name="visual">
                <geometry>
		   <!-- <cylinder>
			  <radius>0.2159</radius>
			  <length>0.1524</length>
		   </cylinder> -->
                   <mesh>
            		<uri>model://rassor2/wheel.dae</uri>
	                <scale>1.0 1.0 1.0</scale>
                    </mesh>
                </geometry>
		<material>
		    <ambient>0.3 0.3 0.3 1</ambient>
		    <diffuse>0.3 0.3 0.3 1</diffuse>
		    <specular>0.1 0.1 0.1 1</specular>
		    <emissive>0 0 0 0</emissive>
		</material>
            </visual>
        </link>
        
        <joint name="left_front" type="revolute">
            <parent>chassis</parent>
            <child>left_front_wheel</child>
            <axis>
                <xyz>0 1 0</xyz>
            </axis>
        </joint>

        <link name="right_front_wheel">
            <pose>0.250 -0.240 0.2159 1.5708 0 0</pose>
	    <inertial>
		<mass>4</mass>
		<inertia>
		  <ixx>0.05</ixx>
		  <ixy>0.0</ixy>
		  <ixz>0.0</ixz>
		  <iyy>0.05</iyy>
		  <iyz>0.0</iyz>
		  <izz>0.09</izz>
		</inertia>
	    </inertial>
            <collision name="collision">
	      <geometry>
		<cylinder>
		  <radius>0.2159</radius><!-- 6 in wide, 17 inch diameter-->
		  <length>0.1524</length>
		</cylinder>
	      </geometry>
		<surface>
		  <friction>
		    <ode>
		      <mu>0.9</mu>
		      <mu2>0.9</mu2>
		      <fdir1>0 0 0</fdir1>
		      <slip1>0.8</slip1>
		      <slip2>0.4</slip2>
		    </ode>
		  </friction>
		</surface>
            </collision>
            <visual name="visual">
                <geometry>
		   <!-- <cylinder>
			  <radius>0.2159</radius>
			  <length>0.1524</length>
		   </cylinder> -->
                   <mesh>
            		<uri>model://rassor2/wheel.dae</uri>
	                <scale>1.0 1.0 1.0</scale>
                    </mesh>
                </geometry>
		<material>
		    <ambient>0.3 0.3 0.3 1</ambient>
		    <diffuse>0.3 0.3 0.3 1</diffuse>
		    <specular>0.1 0.1 0.1 1</specular>
		    <emissive>0 0 0 0</emissive>
		</material>
            </visual>
        </link>
        
        <joint name="right_front" type="revolute">
            <parent>chassis</parent>
            <child>right_front_wheel</child>
            <axis>
                <xyz>0 1 0</xyz>
            </axis>
        </joint>

        <link name="left_rear_wheel">
            <pose>-0.250 0.240 0.2159 -1.5708 0 0</pose>
	    <inertial>
		<mass>4</mass>
		<inertia>
		  <ixx>0.05</ixx>
		  <ixy>0.0</ixy>
		  <ixz>0.0</ixz>
		  <iyy>0.05</iyy>
		  <iyz>0.0</iyz>
		  <izz>0.09</izz>
		</inertia>
	    </inertial>
            <collision name="collision">
	      <geometry>
		<cylinder>
		  <radius>0.2159</radius><!-- 6 in wide, 17 inch diameter-->
		  <length>0.1524</length>
		</cylinder>
	      </geometry>
		<surface>
		  <friction>
		    <ode>
		      <mu>0.9</mu>
		      <mu2>0.9</mu2>
		      <fdir1>0 0 0</fdir1>
		      <slip1>0.8</slip1>
		      <slip2>0.4</slip2>
		    </ode>
		  </friction>
		</surface>
            </collision>
            <visual name="visual">
                <geometry>
		   <!-- <cylinder>
			  <radius>0.2159</radius>
			  <length>0.1524</length>
		   </cylinder> -->
                   <mesh>
            		<uri>model://rassor2/wheel.dae</uri>
	                <scale>1.0 1.0 1.0</scale>
                    </mesh>
                </geometry>
		<material>
		    <ambient>0.3 0.3 0.3 1</ambient>
		    <diffuse>0.3 0.3 0.3 1</diffuse>
		    <specular>0.1 0.1 0.1 1</specular>
		    <emissive>0 0 0 0</emissive>
		</material>
            </visual>
        </link>
        
        <joint name="left_rear" type="revolute">
            <parent>chassis</parent>
            <child>left_rear_wheel</child>
            <axis>
                <xyz>0 1 0</xyz>
            </axis>
        </joint>

        <link name="right_rear_wheel">
            <pose>-0.250 -0.240 0.2159 1.5708 0 0</pose>
	    <inertial>
		<mass>4</mass>
		<inertia>
		  <ixx>0.05</ixx>
		  <ixy>0.0</ixy>
		  <ixz>0.0</ixz>
		  <iyy>0.05</iyy>
		  <iyz>0.0</iyz>
		  <izz>0.09</izz>
		</inertia>
	    </inertial>
            <collision name="collision">
	      <geometry>
		<cylinder>
		  <radius>0.2159</radius><!-- 6 in wide, 17 inch diameter-->
		  <length>0.1524</length>
		</cylinder>
	      </geometry>
		<surface>
		  <friction>
		    <ode>
		      <mu>0.9</mu>
		      <mu2>0.9</mu2>
		      <fdir1>0 0 0</fdir1>
		      <slip1>0.8</slip1>
		      <slip2>0.4</slip2>
		    </ode>
		  </friction>
		</surface>
            </collision>
            <visual name="visual">
                <geometry>
		   <!-- <cylinder>
			  <radius>0.2159</radius>
			  <length>0.1524</length>
		   </cylinder> -->
                   <mesh>
            		<uri>model://rassor2/wheel.dae</uri>
	                <scale>1.0 1.0 1.0</scale>
                    </mesh>
                </geometry>
		<material>
		    <ambient>0.3 0.3 0.3 1</ambient>
		    <diffuse>0.3 0.3 0.3 1</diffuse>
		    <specular>0.1 0.1 0.1 1</specular>
		    <emissive>0 0 0 0</emissive>
		</material>
            </visual>
        </link>
        
        <joint name="right_rear" type="revolute">
            <parent>chassis</parent>
            <child>right_rear_wheel</child>
            <axis>
                <xyz>0 1 0</xyz>
            </axis>
        </joint>   






<!-- front camera definition -->
  <link name="front_camera_link">

	<collision name='collision'>
	  <pose>0.180 0.0 0.880 0 -0.9 0</pose>
	  <geometry>
	    <box>
	      <size>.030 .020 .020</size>
	    </box>
	  </geometry>
	</collision>

	<!-- <visual name='visual'>
	  <pose>0.180 0.0 0.880 0 -0.9 0</pose>
	  <geometry>
	    <box>
	      <size>.030 .020 .020</size>
	    </box>
	  </geometry>
	<material>
	    <ambient>0.5 0.5 1 1</ambient>
	    <diffuse>0.5 0.5 1 1</diffuse>
	    <specular>0.1 0.1 0.1 1</specular>
	    <emissive>0 0 0 0</emissive>
	</material>
	</visual> -->

    <sensor type="camera" name="front_camera">
	  <pose>0.18 0.0 0.880 0 -0.9 0</pose>
      <update_rate>24.0</update_rate>
      <camera name="front">
        <horizontal_fov>1.3962634</horizontal_fov>
        <image>
          <width>800</width>
          <height>600</height>
          <format>R8G8B8</format>
        </image>
        <clip>
          <near>0.02</near>
          <far>300</far>
        </clip>
        <noise>
          <type>gaussian</type>
          <mean>0.0</mean>
          <stddev>0.007</stddev>
        </noise>
      </camera>
      <plugin name="camera_controller" filename="libgazebo_ros_camera.so">
        <alwaysOn>true</alwaysOn>
        <updateRate>24.0</updateRate>
    	<robotNamespace>/rassor2</robotNamespace>
        <cameraName>front_camera</cameraName>
        <imageTopicName>image</imageTopicName>
        <cameraInfoTopicName>front_camera_info</cameraInfoTopicName>
        <frameName>front_camera</frameName>
        <hackBaseline>0.07</hackBaseline>
        <distortionK1>0.0</distortionK1>
        <distortionK2>0.0</distortionK2>
        <distortionK3>0.0</distortionK3>
        <distortionT1>0.0</distortionT1>
        <distortionT2>0.0</distortionT2>
      </plugin>
    </sensor>

  </link>

  <joint name="front_camera_joint" type="revolute">
      <parent>front_arm_link</parent>
      <child>front_camera_link</child>
	  <axis>
	    <xyz>0 1 0</xyz>
	    <limit>
	      <upper>0</upper>
	      <lower>0</lower>
	    </limit>
	  </axis>
  </joint>







	<!-- inertial measurement unit definition -->
	<plugin name="imu_sim" filename="libhector_gazebo_ros_imu.so">
	      <updateRate>10</updateRate>
              <robotNamespace>/rassor2</robotNamespace>
	      <bodyName>chassis</bodyName>
	      <topicName>imu</topicName>
	      <rpyOffsets>0 0 0</rpyOffsets> 
	      <gaussianNoise>99999</gaussianNoise>  
	      <accelDrift>0.2 0.2 0.2</accelDrift>
	      <accelGaussianNoise>0.1 0.1 0.05</accelGaussianNoise>
	      <rateDrift>0.1 0.1 0.1</rateDrift>
	      <rateGaussianNoise>0.05 0.05 0.015</rateGaussianNoise>
	      <headingDrift>0.1</headingDrift>
	      <headingGaussianNoise>99999</headingGaussianNoise>
	</plugin>








<!-- controller for the 4 drive wheels -->
  <plugin name="skid_steer_drive_controller" filename="libgazebo_ros_skid_steer_drive.so">
    <updateRate>10</updateRate>
    <robotNamespace>/rassor2</robotNamespace>
    <leftFrontJoint>left_front</leftFrontJoint>
    <rightFrontJoint>right_front</rightFrontJoint>
    <leftRearJoint>left_rear</leftRearJoint>
    <rightRearJoint>right_rear</rightRearJoint>
    <wheelSeparation>0.460</wheelSeparation>
    <wheelDiameter>0.430</wheelDiameter>
    <robotBaseFrame>chassis</robotBaseFrame>
    <torque>200.0</torque>
    <commandTopic>mobility</commandTopic>
    <odometryTopic>odom_mobility</odometryTopic>
    <odometryFrame>odom</odometryFrame>
  </plugin>





<!-- controller for the front arm -->
  <plugin name="differential_drive_controller" filename="libgazebo_ros_diff_drive.so">
    <alwaysOn>true</alwaysOn>
    <updateRate>10</updateRate>
    <robotNamespace>/rassor2</robotNamespace>
    <leftJoint>front_arm</leftJoint>
    <rightJoint>front_arm</rightJoint>
    <wheelSeparation>0.5</wheelSeparation>
    <wheelDiameter>0.5</wheelDiameter>
    <torque>200</torque>
    <commandTopic>arm_front</commandTopic>
    <odometryTopic>odom_arm_front</odometryTopic>
    <odometryFrame>odom</odometryFrame>
    <robotBaseFrame>chassis</robotBaseFrame>
  </plugin>




<!-- controller for the front left drum -->
  <plugin name="differential_drive_controller" filename="libgazebo_ros_diff_drive.so">
    <alwaysOn>true</alwaysOn>
    <updateRate>10</updateRate>
    <robotNamespace>/rassor2</robotNamespace>
    <leftJoint>front_left_drum</leftJoint>
    <rightJoint>front_left_drum</rightJoint>
    <wheelSeparation>0.5</wheelSeparation>
    <wheelDiameter>0.5</wheelDiameter>
    <torque>200</torque>
    <commandTopic>drum_front_left</commandTopic>
    <odometryTopic>odom_front_left</odometryTopic>
    <odometryFrame>odom</odometryFrame>
    <robotBaseFrame>chassis</robotBaseFrame>
  </plugin>




<!-- controller for the front right drum -->
  <plugin name="differential_drive_controller" filename="libgazebo_ros_diff_drive.so">
    <alwaysOn>true</alwaysOn>
    <updateRate>10</updateRate>
    <robotNamespace>/rassor2</robotNamespace>
    <leftJoint>front_right_drum</leftJoint>
    <rightJoint>front_right_drum</rightJoint>
    <wheelSeparation>0.5</wheelSeparation>
    <wheelDiameter>0.5</wheelDiameter>
    <torque>200</torque>
    <commandTopic>drum_front_right</commandTopic>
    <odometryTopic>odom_front_right</odometryTopic>
    <odometryFrame>odom</odometryFrame>
    <robotBaseFrame>chassis</robotBaseFrame>
  </plugin>




<!-- controller for the rear arm -->
  <plugin name="differential_drive_controller" filename="libgazebo_ros_diff_drive.so">
    <alwaysOn>true</alwaysOn>
    <updateRate>10</updateRate>
    <robotNamespace>/rassor2</robotNamespace>
    <leftJoint>rear_arm</leftJoint>
    <rightJoint>rear_arm</rightJoint>
    <wheelSeparation>0.5</wheelSeparation>
    <wheelDiameter>0.5</wheelDiameter>
    <torque>200</torque>
    <commandTopic>arm_rear</commandTopic>
    <odometryTopic>odom3</odometryTopic>
    <odometryFrame>odom3</odometryFrame>
    <robotBaseFrame>chassis</robotBaseFrame>
  </plugin>



<!-- controller for the rear left drum -->
  <plugin name="differential_drive_controller" filename="libgazebo_ros_diff_drive.so">
    <alwaysOn>true</alwaysOn>
    <updateRate>10</updateRate>
    <robotNamespace>/rassor2</robotNamespace>
    <leftJoint>rear_left_drum</leftJoint>
    <rightJoint>rear_left_drum</rightJoint>
    <wheelSeparation>0.5</wheelSeparation>
    <wheelDiameter>0.5</wheelDiameter>
    <torque>200</torque>
    <commandTopic>drum_rear_left</commandTopic>
    <odometryTopic>odom_rear_left</odometryTopic>
    <odometryFrame>odom</odometryFrame>
    <robotBaseFrame>chassis</robotBaseFrame>
  </plugin>




<!-- controller for the rear right drum -->
  <plugin name="differential_drive_controller" filename="libgazebo_ros_diff_drive.so">
    <alwaysOn>true</alwaysOn>
    <updateRate>10</updateRate>
    <robotNamespace>/rassor2</robotNamespace>
    <leftJoint>rear_right_drum</leftJoint>
    <rightJoint>rear_right_drum</rightJoint>
    <wheelSeparation>0.5</wheelSeparation>
    <wheelDiameter>0.5</wheelDiameter>
    <torque>200</torque>
    <commandTopic>drum_rear_right</commandTopic>
    <odometryTopic>odom_rear_right</odometryTopic>
    <odometryFrame>odom</odometryFrame>
    <robotBaseFrame>chassis</robotBaseFrame>
  </plugin>





  </model>
</sdf>





