<sdf version='1.4'>
  <world name='default'>
    <light name='sun' type='directional'>
      <cast_shadows>1</cast_shadows>
      <pose>0 0 10 0 -0 0</pose>
      <diffuse>0.8 0.8 0.8 1</diffuse>
      <specular>0.2 0.2 0.2 1</specular>
      <attenuation>
        <range>1000</range>
        <constant>0.9</constant>
        <linear>0.01</linear>
        <quadratic>0.001</quadratic>
      </attenuation>
      <direction>-0.5 0.1 -0.9</direction>
    </light>
    <model name='ground_plane'>
      <static>1</static>
      <link name='link'>
        <collision name='collision'>
          <geometry>
            <plane>
              <normal>0 0 1</normal>
              <size>100 100</size>
            </plane>
          </geometry>
          <surface>
            <friction>
              <ode>
                <mu>100</mu>
                <mu2>50</mu2>
              </ode>
            </friction>
            <bounce/>
            <contact>
              <ode/>
            </contact>
          </surface>
          <max_contacts>10</max_contacts>
        </collision>
        <visual name='visual'>
          <cast_shadows>0</cast_shadows>
          <geometry>
            <plane>
              <normal>0 0 1</normal>
              <size>100 100</size>
            </plane>
          </geometry>
          <material>
            <script>
              <uri>file://media/materials/scripts/gazebo.material</uri>
              <name>Gazebo/Grey</name>
            </script>
          </material>
        </visual>
        <velocity_decay>
          <linear>0</linear>
          <angular>0</angular>
        </velocity_decay>
        <self_collide>0</self_collide>
        <kinematic>0</kinematic>
        <gravity>1</gravity>
      </link>
    </model>
    <physics type='ode'>
      <max_step_size>0.001</max_step_size>
      <real_time_factor>1</real_time_factor>
      <real_time_update_rate>1000</real_time_update_rate>
      <gravity>0 0 -9.8</gravity>
    </physics>
    <scene>
      <ambient>0.4 0.4 0.4 1</ambient>
      <background>0.7 0.7 0.7 1</background>
      <shadows>1</shadows>
    </scene>
    <model name='rex'>
      <static>0</static>
      <link name='chassis'>
        <pose>0 0 0.048 0 -0 0</pose>
        <inertial>
          <inertia>
            <ixx>0.3</ixx>
            <ixy>0.01</ixy>
            <ixz>0.01</ixz>
            <iyy>0.3</iyy>
            <iyz>0.01</iyz>
            <izz>2</izz>
          </inertia>
          <mass>5</mass>
        </inertial>
        <collision name='collision'>
          <pose>0 0 0.06 0 -0 0</pose>
          <geometry>
            <box>
              <size>0.308 0.18 0.136</size>
            </box>
          </geometry>
          <max_contacts>10</max_contacts>
          <surface>
            <bounce/>
            <friction>
              <ode/>
            </friction>
            <contact>
              <ode/>
            </contact>
          </surface>
        </collision>
        <visual name='visual'>
          <geometry>
            <mesh>
              <uri>model://rex/meshes/Swarmie_Chassis_V2.dae</uri>
            </mesh>
          </geometry>
          <material>
            <script>
              <name>Gazebo/FlatBlack</name>
              <uri>__default__</uri>
            </script>
          </material>
        </visual>
        <velocity_decay>
          <linear>0</linear>
          <angular>0</angular>
        </velocity_decay>
        <self_collide>0</self_collide>
        <kinematic>0</kinematic>
        <gravity>1</gravity>
      </link>
      <link name='top'>
        <pose>0 0 0.184 0 -0 0</pose>
        <collision name='collision'>
          <geometry>
            <box>
              <size>0.209 0.298 0.001</size>
            </box>
          </geometry>
          <max_contacts>10</max_contacts>
          <surface>
            <bounce/>
            <friction>
              <ode/>
            </friction>
            <contact>
              <ode/>
            </contact>
          </surface>
        </collision>
        <visual name='visual'>
          <geometry>
            <mesh>
              <uri>model://rex/meshes/Swarmie_Top_V2.dae</uri>
            </mesh>
          </geometry>
          <material>
            <script>
              <name>Gazebo/Purple</name>
              <uri>__default__</uri>
            </script>
          </material>
        </visual>
        <velocity_decay>
          <linear>0</linear>
          <angular>0</angular>
        </velocity_decay>
        <self_collide>0</self_collide>
        <inertial>
          <inertia>
            <ixx>1</ixx>
            <ixy>0</ixy>
            <ixz>0</ixz>
            <iyy>1</iyy>
            <iyz>0</iyz>
            <izz>1</izz>
          </inertia>
          <mass>1</mass>
        </inertial>
        <kinematic>0</kinematic>
        <gravity>1</gravity>
      </link>
      <joint name='top' type='revolute'>
        <parent>chassis</parent>
        <child>top</child>
        <axis>
          <xyz>0 0 0</xyz>
          <limit>
            <upper>0</upper>
            <lower>0</lower>
          </limit>
        </axis>
      </joint>
      <link name='left_front_wheel'>
        <pose>0.094 0.1295 0.06 1.5708 -0 0</pose>
        <collision name='collision'>
          <geometry>
            <cylinder>
              <radius>0.06</radius>
              <length>0.064</length>
            </cylinder>
          </geometry>
          <surface>
            <bounce>
              <restitution_coefficient>0</restitution_coefficient>
              <threshold>200000</threshold>
            </bounce>
            <friction>
              <ode>
                <mu>1</mu>
                <mu2>1</mu2>
                <slip1>1</slip1>
                <slip2>1</slip2>
              </ode>
            </friction>
            <contact>
              <ode/>
            </contact>
          </surface>
          <max_contacts>10</max_contacts>
        </collision>
        <visual name='visual'>
          <geometry>
            <mesh>
              <uri>model://rex/meshes/Swarmie_Tire_V2.dae</uri>
            </mesh>
          </geometry>
          <material>
            <script>
              <name>Gazebo/Grey</name>
              <uri>__default__</uri>
            </script>
          </material>
        </visual>
        <velocity_decay>
          <linear>0</linear>
          <angular>0</angular>
        </velocity_decay>
        <self_collide>0</self_collide>
        <inertial>
          <inertia>
            <ixx>1</ixx>
            <ixy>0</ixy>
            <ixz>0</ixz>
            <iyy>1</iyy>
            <iyz>0</iyz>
            <izz>1</izz>
          </inertia>
          <mass>1</mass>
        </inertial>
        <kinematic>0</kinematic>
        <gravity>1</gravity>
      </link>
      <joint name='left_front' type='revolute'>
        <parent>chassis</parent>
        <child>left_front_wheel</child>
        <axis>
          <xyz>0 1 0</xyz>
          <limit>
            <lower>-1e+16</lower>
            <upper>1e+16</upper>
          </limit>
        </axis>
      </joint>
      <link name='right_front_wheel'>
        <pose>0.094 -0.1295 0.06 1.5708 -0 0</pose>
        <collision name='collision'>
          <geometry>
            <cylinder>
              <radius>0.06</radius>
              <length>0.064</length>
            </cylinder>
          </geometry>
          <surface>
            <bounce>
              <restitution_coefficient>0</restitution_coefficient>
              <threshold>200000</threshold>
            </bounce>
            <friction>
              <ode>
                <mu>1</mu>
                <mu2>1</mu2>
                <slip1>1</slip1>
                <slip2>1</slip2>
              </ode>
            </friction>
            <contact>
              <ode/>
            </contact>
          </surface>
          <max_contacts>10</max_contacts>
        </collision>
        <visual name='visual'>
          <geometry>
            <mesh>
              <uri>model://rex/meshes/Swarmie_Tire_V2.dae</uri>
            </mesh>
          </geometry>
          <material>
            <script>
              <name>Gazebo/Grey</name>
              <uri>__default__</uri>
            </script>
          </material>
        </visual>
        <velocity_decay>
          <linear>0</linear>
          <angular>0</angular>
        </velocity_decay>
        <self_collide>0</self_collide>
        <inertial>
          <inertia>
            <ixx>1</ixx>
            <ixy>0</ixy>
            <ixz>0</ixz>
            <iyy>1</iyy>
            <iyz>0</iyz>
            <izz>1</izz>
          </inertia>
          <mass>1</mass>
        </inertial>
        <kinematic>0</kinematic>
        <gravity>1</gravity>
      </link>
      <joint name='right_front' type='revolute'>
        <parent>chassis</parent>
        <child>right_front_wheel</child>
        <axis>
          <xyz>0 1 0</xyz>
          <limit>
            <lower>-1e+16</lower>
            <upper>1e+16</upper>
          </limit>
        </axis>
      </joint>
      <link name='left_rear_wheel'>
        <pose>-0.094 0.1295 0.06 1.5708 -0 0</pose>
        <collision name='collision'>
          <geometry>
            <cylinder>
              <radius>0.06</radius>
              <length>0.064</length>
            </cylinder>
          </geometry>
          <surface>
            <bounce>
              <restitution_coefficient>0</restitution_coefficient>
              <threshold>200000</threshold>
            </bounce>
            <friction>
              <ode>
                <mu>1</mu>
                <mu2>1</mu2>
                <slip1>1</slip1>
                <slip2>1</slip2>
              </ode>
            </friction>
            <contact>
              <ode/>
            </contact>
          </surface>
          <max_contacts>10</max_contacts>
        </collision>
        <visual name='visual'>
          <geometry>
            <mesh>
              <uri>model://rex/meshes/Swarmie_Tire_V2.dae</uri>
            </mesh>
          </geometry>
          <material>
            <script>
              <name>Gazebo/Grey</name>
              <uri>__default__</uri>
            </script>
          </material>
        </visual>
        <velocity_decay>
          <linear>0</linear>
          <angular>0</angular>
        </velocity_decay>
        <self_collide>0</self_collide>
        <inertial>
          <inertia>
            <ixx>1</ixx>
            <ixy>0</ixy>
            <ixz>0</ixz>
            <iyy>1</iyy>
            <iyz>0</iyz>
            <izz>1</izz>
          </inertia>
          <mass>1</mass>
        </inertial>
        <kinematic>0</kinematic>
        <gravity>1</gravity>
      </link>
      <joint name='left_rear' type='revolute'>
        <parent>chassis</parent>
        <child>left_rear_wheel</child>
        <axis>
          <xyz>0 1 0</xyz>
          <limit>
            <lower>-1e+16</lower>
            <upper>1e+16</upper>
          </limit>
        </axis>
      </joint>
      <link name='right_rear_wheel'>
        <pose>-0.094 -0.1295 0.06 1.5708 -0 0</pose>
        <collision name='collision'>
          <geometry>
            <cylinder>
              <radius>0.06</radius>
              <length>0.064</length>
            </cylinder>
          </geometry>
          <surface>
            <bounce>
              <restitution_coefficient>0</restitution_coefficient>
              <threshold>200000</threshold>
            </bounce>
            <friction>
              <ode>
                <mu>1</mu>
                <mu2>1</mu2>
                <slip1>1</slip1>
                <slip2>1</slip2>
              </ode>
            </friction>
            <contact>
              <ode/>
            </contact>
          </surface>
          <max_contacts>10</max_contacts>
        </collision>
        <visual name='visual'>
          <geometry>
            <mesh>
              <uri>model://rex/meshes/Swarmie_Tire_V2.dae</uri>
            </mesh>
          </geometry>
          <material>
            <script>
              <name>Gazebo/Grey</name>
              <uri>__default__</uri>
            </script>
          </material>
        </visual>
        <velocity_decay>
          <linear>0</linear>
          <angular>0</angular>
        </velocity_decay>
        <self_collide>0</self_collide>
        <inertial>
          <inertia>
            <ixx>1</ixx>
            <ixy>0</ixy>
            <ixz>0</ixz>
            <iyy>1</iyy>
            <iyz>0</iyz>
            <izz>1</izz>
          </inertia>
          <mass>1</mass>
        </inertial>
        <kinematic>0</kinematic>
        <gravity>1</gravity>
      </link>
      <joint name='right_rear' type='revolute'>
        <parent>chassis</parent>
        <child>right_rear_wheel</child>
        <axis>
          <xyz>0 1 0</xyz>
          <limit>
            <lower>-1e+16</lower>
            <upper>1e+16</upper>
          </limit>
        </axis>
      </joint>
      <joint name='us_center_joint' type='revolute'>
        <parent>chassis</parent>
        <child>us_center_link</child>
        <axis>
          <xyz>0 0 1</xyz>
          <limit>
            <upper>0</upper>
            <lower>0</lower>
          </limit>
        </axis>
      </joint>
      <link name='us_center_link'>
        <visual name='visual'>
          <pose>0.11 0 0.122 0 0 -1.5708</pose>
          <geometry>
            <mesh>
              <uri>model://rex/meshes/SwarmieUS_V2.dae</uri>
            </mesh>
          </geometry>
          <material>
            <script>
              <name>Gazebo/Green</name>
              <uri>__default__</uri>
            </script>
          </material>
        </visual>
        <sensor name='us_center_sensor' type='ray'>
          <pose>0.165 0 0.122 0 -0 0</pose>
          <visualize>1</visualize>
          <update_rate>5</update_rate>
          <ray>
            <scan>
              <horizontal>
                <samples>5</samples>
                <resolution>1</resolution>
                <min_angle>-0.2618</min_angle>
                <max_angle>0.2618</max_angle>
              </horizontal>
            </scan>
            <range>
              <min>0.01</min>
              <max>0.5</max>
              <resolution>0.01</resolution>
            </range>
          </ray>
          <plugin name='us' filename='libhector_gazebo_ros_sonar.so'>
            <topicName>/rex/USCenter</topicName>
            <frameId>us_center_link</frameId>
          </plugin>
        </sensor>
        <velocity_decay>
          <linear>0</linear>
          <angular>0</angular>
        </velocity_decay>
        <self_collide>0</self_collide>
        <inertial>
          <inertia>
            <ixx>1</ixx>
            <ixy>0</ixy>
            <ixz>0</ixz>
            <iyy>1</iyy>
            <iyz>0</iyz>
            <izz>1</izz>
          </inertia>
          <mass>1</mass>
        </inertial>
        <kinematic>0</kinematic>
        <gravity>1</gravity>
      </link>
      <joint name='us_right_joint' type='revolute'>
        <parent>chassis</parent>
        <child>us_right_link</child>
        <axis>
          <xyz>0 0 1</xyz>
          <limit>
            <upper>0</upper>
            <lower>0</lower>
          </limit>
        </axis>
      </joint>
      <link name='us_right_link'>
        <visual name='visual'>
          <pose>0.1 -0.048 0.122 0 0 -2.0071</pose>
          <geometry>
            <mesh>
              <uri>model://rex/meshes/SwarmieUS_V2.dae</uri>
            </mesh>
          </geometry>
          <material>
            <script>
              <name>Gazebo/Green</name>
              <uri>__default__</uri>
            </script>
          </material>
        </visual>
        <sensor name='us_right_sensor' type='ray'>
          <pose>0.16 -0.055 0.122 0 0 -0.43633</pose>
          <visualize>1</visualize>
          <update_rate>5</update_rate>
          <ray>
            <scan>
              <horizontal>
                <samples>5</samples>
                <resolution>1</resolution>
                <min_angle>-0.2618</min_angle>
                <max_angle>0.2618</max_angle>
              </horizontal>
            </scan>
            <range>
              <min>0.01</min>
              <max>0.5</max>
              <resolution>0.01</resolution>
            </range>
          </ray>
          <plugin name='us' filename='libhector_gazebo_ros_sonar.so'>
            <topicName>/rex/USRight</topicName>
            <frameId>us_center_link</frameId>
          </plugin>
        </sensor>
        <velocity_decay>
          <linear>0</linear>
          <angular>0</angular>
        </velocity_decay>
        <self_collide>0</self_collide>
        <inertial>
          <inertia>
            <ixx>1</ixx>
            <ixy>0</ixy>
            <ixz>0</ixz>
            <iyy>1</iyy>
            <iyz>0</iyz>
            <izz>1</izz>
          </inertia>
          <mass>1</mass>
        </inertial>
        <kinematic>0</kinematic>
        <gravity>1</gravity>
      </link>
      <joint name='us_left_joint' type='revolute'>
        <parent>chassis</parent>
        <child>us_left_link</child>
        <axis>
          <xyz>0 0 1</xyz>
          <limit>
            <upper>0</upper>
            <lower>0</lower>
          </limit>
        </axis>
      </joint>
      <link name='us_left_link'>
        <visual name='visual'>
          <pose>0.1 0.048 0.122 0 0 -1.1345</pose>
          <geometry>
            <mesh>
              <uri>model://rex/meshes/SwarmieUS_V2.dae</uri>
            </mesh>
          </geometry>
          <material>
            <script>
              <name>Gazebo/Green</name>
              <uri>__default__</uri>
            </script>
          </material>
        </visual>
        <sensor name='us_left_sensor' type='ray'>
          <pose>0.16 0.055 0.122 0 -0 0.43633</pose>
          <visualize>1</visualize>
          <update_rate>5</update_rate>
          <ray>
            <scan>
              <horizontal>
                <samples>5</samples>
                <resolution>1</resolution>
                <min_angle>-0.2618</min_angle>
                <max_angle>0.2618</max_angle>
              </horizontal>
            </scan>
            <range>
              <min>0.01</min>
              <max>0.5</max>
              <resolution>0.01</resolution>
            </range>
          </ray>
          <plugin name='us' filename='libhector_gazebo_ros_sonar.so'>
            <topicName>/rex/USLeft</topicName>
            <frameId>us_center_link</frameId>
          </plugin>
        </sensor>
        <velocity_decay>
          <linear>0</linear>
          <angular>0</angular>
        </velocity_decay>
        <self_collide>0</self_collide>
        <inertial>
          <inertia>
            <ixx>1</ixx>
            <ixy>0</ixy>
            <ixz>0</ixz>
            <iyy>1</iyy>
            <iyz>0</iyz>
            <izz>1</izz>
          </inertia>
          <mass>1</mass>
        </inertial>
        <kinematic>0</kinematic>
        <gravity>1</gravity>
      </link>
      <joint name='camera_joint' type='revolute'>
        <parent>chassis</parent>
        <child>camera_link</child>
        <axis>
          <xyz>0 1 0</xyz>
          <limit>
            <upper>0</upper>
            <lower>0</lower>
          </limit>
        </axis>
      </joint>
      <link name='camera_link'>
        <visual name='visual'>
          <pose>0.072 0 0.11 0 -0 1.5708</pose>
          <geometry>
            <mesh>
              <uri>model://rex/meshes/Swarmie_Camera_V2.dae</uri>
            </mesh>
          </geometry>
          <material>
            <script>
              <name>Gazebo/Grey</name>
              <uri>__default__</uri>
            </script>
          </material>
        </visual>
        <sensor name='camera' type='camera'>
          <pose>0.089 -0.01 0.161 0 -0 0</pose>
          <update_rate>6</update_rate>
          <camera name='head'>
            <horizontal_fov>1.39626</horizontal_fov>
            <image>
              <width>640</width>
              <height>320</height>
              <format>R8G8B8</format>
            </image>
            <clip>
              <near>0.02</near>
              <far>300</far>
            </clip>
            <noise>
              <type>gaussian</type>
              <mean>0</mean>
              <stddev>0.007</stddev>
            </noise>
          </camera>
          <plugin name='camera_controller' filename='libgazebo_ros_camera.so'>
            <alwaysOn>true</alwaysOn>
            <updateRate>0.0</updateRate>
            <cameraName>/rex/camera</cameraName>
            <imageTopicName>/rex/camera/image</imageTopicName>
            <cameraInfoTopicName>/rex/camera/info</cameraInfoTopicName>
            <frameName>camera_link</frameName>
            <hackBaseline>0.07</hackBaseline>
            <distortionK1>0.0</distortionK1>
            <distortionK2>0.0</distortionK2>
            <distortionK3>0.0</distortionK3>
            <distortionT1>0.0</distortionT1>
            <distortionT2>0.0</distortionT2>
          </plugin>
        </sensor>
        <velocity_decay>
          <linear>0</linear>
          <angular>0</angular>
        </velocity_decay>
        <self_collide>0</self_collide>
        <inertial>
          <inertia>
            <ixx>1</ixx>
            <ixy>0</ixy>
            <ixz>0</ixz>
            <iyy>1</iyy>
            <iyz>0</iyz>
            <izz>1</izz>
          </inertia>
          <mass>1</mass>
        </inertial>
        <kinematic>0</kinematic>
        <gravity>1</gravity>
      </link>
      <plugin name='skid_steer_drive_controller' filename='libgazebo_ros_skid_steer_drive.so'>
        <updateRate>10</updateRate>
        <robotNamespace>/</robotNamespace>
        <leftFrontJoint>left_front</leftFrontJoint>
        <rightFrontJoint>right_front</rightFrontJoint>
        <leftRearJoint>left_rear</leftRearJoint>
        <rightRearJoint>right_rear</rightRearJoint>
        <wheelSeparation>0.187</wheelSeparation>
        <wheelDiameter>0.120</wheelDiameter>
        <robotBaseFrame>chassis</robotBaseFrame>
        <torque>2.8</torque>
        <commandTopic>/rex/mobility</commandTopic>
        <odometryTopic>/rex/odom</odometryTopic>
        <odometryFrame>odom</odometryFrame>
      </plugin>
      <pose>0 0 0 0 -0 0</pose>
    </model>
    <model name='at5'>
      <link name='link'>
        <pose>0 0 0.1 0 -0 0</pose>
        <collision name='collision'>
          <geometry>
            <box>
              <size>0.279 0.216 0.216</size>
            </box>
          </geometry>
          <max_contacts>10</max_contacts>
          <surface>
            <bounce/>
            <friction>
              <ode/>
            </friction>
            <contact>
              <ode/>
            </contact>
          </surface>
        </collision>
        <visual name='visual'>
          <geometry>
            <box>
              <size>0.279 0.216 0.216</size>
            </box>
          </geometry>
          <material>
            <script>
              <uri>model://at5/materials/scripts</uri>
              <uri>model://at5/materials/textures</uri>
              <name>at5/Diffuse</name>
            </script>
          </material>
        </visual>
        <velocity_decay>
          <linear>0</linear>
          <angular>0</angular>
        </velocity_decay>
        <self_collide>0</self_collide>
        <inertial>
          <inertia>
            <ixx>1</ixx>
            <ixy>0</ixy>
            <ixz>0</ixz>
            <iyy>1</iyy>
            <iyz>0</iyz>
            <izz>1</izz>
          </inertia>
          <mass>1</mass>
        </inertial>
        <kinematic>0</kinematic>
        <gravity>1</gravity>
      </link>
      <pose>1 0 0 0 -0 0</pose>
      <static>0</static>
    </model>
    <state world_name='default'>
      <sim_time>700 187000000</sim_time>
      <real_time>730 351025866</real_time>
      <wall_time>1404919239 50301827</wall_time>
      <model name='at5'>
        <pose>1 0 0.008 1e-06 1e-06 -1e-06</pose>
        <link name='link'>
          <pose>1 -0 0.108 1e-06 1e-06 -1e-06</pose>
          <velocity>0 0 0 0 -0 0</velocity>
          <acceleration>0 0 0 0 -0 0</acceleration>
          <wrench>0 0 0 0 -0 0</wrench>
        </link>
      </model>
      <model name='ground_plane'>
        <pose>0 0 0 0 -0 0</pose>
        <link name='link'>
          <pose>0 0 0 0 -0 0</pose>
          <velocity>0 0 0 0 -0 0</velocity>
          <acceleration>0 0 0 0 -0 0</acceleration>
          <wrench>0 0 0 0 -0 0</wrench>
        </link>
      </model>
      <model name='rex'>
        <pose>-0.217152 0.003112 0 -1e-06 3e-06 0.520979</pose>
        <link name='camera_link'>
          <pose>-0.217152 0.003112 0 -1e-06 3e-06 0.520979</pose>
          <velocity>2e-06 3e-06 6.7e-05 -0.000476 0.000383 1e-06</velocity>
          <acceleration>0 0 0 0 -0 0</acceleration>
          <wrench>0 0 0 0 -0 0</wrench>
        </link>
        <link name='chassis'>
          <pose>-0.217152 0.003112 0.048 -1e-06 3e-06 0.520979</pose>
          <velocity>2.1e-05 2.1e-05 6.6e-05 -0.000372 0.000376 2.64698e-23</velocity>
          <acceleration>0 0 0 0 -0 0</acceleration>
          <wrench>0 0 0 0 -0 0</wrench>
        </link>
        <link name='left_front_wheel'>
          <pose>-0.200079 0.162218 0.06 1.5708 0.618227 0.520978</pose>
          <velocity>2.4e-05 1.8e-05 1.8e-05 -0.000305 0.000403 -2.64698e-23</velocity>
          <acceleration>0 0 0 0 -0 0</acceleration>
          <wrench>0 0 0 0 -0 0</wrench>
        </link>
        <link name='left_rear_wheel'>
          <pose>-0.363137 0.068645 0.06 1.5708 0.614948 0.520977</pose>
          <velocity>2.2e-05 2.2e-05 0.000129 -0.000371 0.000372 1e-06</velocity>
          <acceleration>0 0 0 0 -0 0</acceleration>
          <wrench>0 0 0 0 -0 0</wrench>
        </link>
        <link name='right_front_wheel'>
          <pose>-0.071167 -0.062421 0.06 -1.57079 -0.855773 -2.62062</pose>
          <velocity>2.5e-05 1.9e-05 6e-06 -0.000315 0.00042 1e-06</velocity>
          <acceleration>0 0 0 0 -0 0</acceleration>
          <wrench>0 0 0 0 -0 0</wrench>
        </link>
        <link name='right_rear_wheel'>
          <pose>-0.234226 -0.155994 0.060001 -1.57079 -0.858016 -2.62062</pose>
          <velocity>2.2e-05 2.5e-05 0.000135 -0.000442 0.000344 1e-06</velocity>
          <acceleration>0 0 0 0 -0 0</acceleration>
          <wrench>0 0 0 0 -0 0</wrench>
        </link>
        <link name='top'>
          <pose>-0.217152 0.003113 0.184 -1e-06 4e-06 0.520979</pose>
          <velocity>6.9e-05 5.9e-05 6.5e-05 -0.000344 0.00037 -2.64698e-23</velocity>
          <acceleration>0 0 0 0 -0 0</acceleration>
          <wrench>0 0 0 0 -0 0</wrench>
        </link>
        <link name='us_center_link'>
          <pose>-0.217152 0.003112 0 -1e-06 4e-06 0.520979</pose>
          <velocity>6e-06 -5e-06 6.8e-05 -0.000503 0.000289 -3.2e-05</velocity>
          <acceleration>0 0 0 0 -0 0</acceleration>
          <wrench>0 0 0 0 -0 0</wrench>
        </link>
        <link name='us_left_link'>
          <pose>-0.217152 0.003112 0 -1e-06 3e-06 0.520979</pose>
          <velocity>2e-06 -3e-06 6.7e-05 -0.000545 0.000352 8.8e-05</velocity>
          <acceleration>0 0 0 0 -0 0</acceleration>
          <wrench>0 0 0 0 -0 0</wrench>
        </link>
        <link name='us_right_link'>
          <pose>-0.217152 0.003112 0 -1e-06 3e-06 0.520979</pose>
          <velocity>4e-06 -6e-06 6.8e-05 -0.000558 0.00032 -4.7e-05</velocity>
          <acceleration>0 0 0 0 -0 0</acceleration>
          <wrench>0 0 0 0 -0 0</wrench>
        </link>
      </model>
    </state>
    <gui fullscreen='0'>
      <camera name='user_camera'>
        <pose>3.05819 -2.36885 1.10945 0 0.275643 2.35619</pose>
        <view_controller>orbit</view_controller>
      </camera>
    </gui>
  </world>
</sdf>
