<?xml version='1.0'?>
<sdf version='1.4'>
	<model name="achilles">

		<static>false</static>

		<link name='base_link'>
			<inertial>
				<mass>10.0</mass>
				<inertia>
					<ixx>0.04</ixx>
					<ixy>0.0</ixy>
					<ixz>0.0</ixz>
					<iyy>0.04</iyy>
					<iyz>0.0</iyz>
					<izz>0.07</izz>
				</inertia>
			</inertial>
			<collision name='collision'>
				<pose>0 0 0.03 0 0 0</pose>
				<geometry>
					<box>
						<size>0.26 0.205 0.18</size>
					</box>
				</geometry>
			</collision>
			<visual name='visual'>
				<pose>0 0 -0.06 0 0 0</pose>
				<geometry>
					<mesh>
						<uri>model://swarmie/meshes/Body.stl</uri>
					</mesh>
				</geometry>
				<material>
					<script>
						<name>Gazebo/Grey</name>
					</script>
				</material>
			</visual>
		</link>

		<link name='top'>
			<pose>0.0006 0 0.12 0 0 0</pose>
			<inertial>
				<mass>0.2</mass>
				<inertia>
					<ixx>0.0001</ixx>
					<ixy>0.0</ixy>
					<ixz>0.0</ixz>
					<iyy>0.0001</iyy>
					<iyz>0.0</iyz>
					<izz>0.0002</izz>
				</inertia>
			</inertial>
			<collision name='collision'>
				<pose>0 0 0 0 0 0</pose>
				<geometry>
					<box>
						<size>0.25 0.30 0.005</size>
					</box>
				</geometry>
			</collision>
			<visual name='visual'>
				<geometry>
					<mesh>
						<uri>model://swarmie/meshes/CoverPlate.stl</uri>
					</mesh>
				</geometry>
				<material>
					<script>
						<name>Gazebo/FlatBlack</name>
					</script>
				</material>
			</visual>
		</link>

		<joint name="top" type="revolute">
			<parent>base_link</parent>
			<child>top</child>
			<axis>
				<xyz>0 0 0</xyz>
				<limit>
					<upper>0</upper>
					<lower>0</lower>
				</limit>
			</axis>
		</joint>

	<link name="gripper_wrist">
			<inertial>
				<mass>0.085</mass>
				<inertia>
					<ixx>0.00005</ixx>
					<ixy>0.0</ixy>
					<ixz>0.0</ixz>
					<iyy>0.00006</iyy>
					<iyz>0.0</iyz>
					<izz>0.00005</izz>
				</inertia>
			</inertial>
			<visual name="visual">
				<pose>0 0 -0.06 0 0 0</pose>
				<geometry>
					<mesh>
						<uri>model://swarmie/meshes/GripperWrist.stl</uri>
					</mesh>
				</geometry>
				<material>
					<script>
						<name>Gazebo/Grey</name>
					</script>
				</material>
			</visual>
			<collision name="collision">
				<pose>0.16 0 -0.022 0 0 1.57</pose>
				<geometry>
					<box>
						<size>0.10 0.05 0.065</size>
					</box>
				</geometry>
			</collision>
		</link>

		<joint name="gripper_wrist_joint" type="revolute">
			<parent>base_link</parent>
			<child>gripper_wrist</child>
			<pose>0.136 0 -0.029 0 0 0</pose>
			<axis>
				<xyz>0 1 0</xyz>
				<limit>
					<upper>0.7854</upper>
					<lower>0.0</lower>
				</limit>
				<dynamics>
				  <damping>0.3</damping>
				</dynamics>
			</axis>
		</joint>

		<link name="gripper_left_finger">
			<inertial>
				<mass>0.005</mass>
				<inertia>
					<ixx>0.000002</ixx>
					<ixy>0.0</ixy>
					<ixz>0.0</ixz>
					<iyy>0.000002</iyy>
					<iyz>0.0</iyz>
					<izz>0.000004</izz>
				</inertia>
			</inertial>
			<collision name="collision">
				<pose>0.215 0.018 0.01 0 0 -0.38</pose>
				<geometry>
					<box>
						<size>0.06 0.01 0.007</size>
					</box>
				</geometry>
				<surface>
					<friction>
						<ode>
							<mu>0.8</mu>
							<mu2>0.7</mu2>
						</ode>
					</friction>
				</surface>
			</collision>
			<collision name="collision2">
				<pose>0.2475 0.007 0.01 0 0 -0.38</pose>
				<geometry>
					<box>
						<size>0.01 0.01 0.007</size>
					</box>
				</geometry>
				<surface>
					<friction>
						<ode>
							<mu>0.8</mu>
							<mu2>0.7</mu2>
						</ode>
					</friction>
				</surface>
			</collision>
			<visual name="visual">
				<pose>0 0 -0.06 0 0 0.0</pose>
				<geometry>
					<mesh>
						<uri>model://swarmie/meshes/GripperFingerLeft.stl</uri>
					</mesh>
				</geometry>
				<material>
					<script>
						<name>Gazebo/Grey</name>
					</script>
				</material>
			</visual>
			<sensor name='finger' type='contact'>
			  <contact>
			    <collision>collision</collision>
			  </contact>
			</sensor>
		</link>

		<joint name ="gripper_left_finger_joint" type="revolute">
			<parent>gripper_wrist</parent>
			<child>gripper_left_finger</child>
			<pose>0.1825 0.02175 0 0 0 0</pose>
			<axis>
				<xyz>0 0 1</xyz>
				<limit>
					<upper>0.7854</upper>
					<lower>0.0</lower>
				</limit>
				<dynamics>
				  <damping>0.3</damping>
				</dynamics>
			</axis>
		</joint>

		<link name="gripper_right_finger">
			<inertial>
				<mass>0.005</mass>
				<inertia>
					<ixx>0.000002</ixx>
					<ixy>0.0</ixy>
					<ixz>0.0</ixz>
					<iyy>0.000002</iyy>
					<iyz>0.0</iyz>
					<izz>0.000004</izz>
				</inertia>
			</inertial>
			<collision name="collision">
				<pose>0.215 -0.018 0.01 0 0 0.38</pose>
				<geometry>
					<box>
						<size>0.06 0.01 0.007</size>
					</box>
				</geometry>
				<surface>
					<friction>
						<ode>
							<mu>0.8</mu>
							<mu2>0.7</mu2>
						</ode>
					</friction>
				</surface>
			</collision>
			<collision name="collision2">
				<pose>0.2475 -0.007 0.01 0 0 0.38</pose>
				<geometry>
					<box>
						<size>0.01 0.01 0.007</size>
					</box>
				</geometry>
				<surface>
					<friction>
						<ode>
							<mu>0.8</mu>
							<mu2>0.7</mu2>
						</ode>
					</friction>
				</surface>
			</collision>
			<visual name="visual">
				<pose>0 0 -0.06 0 0 0</pose>
				<geometry>
					<mesh>
						<uri>model://swarmie/meshes/GripperFingerRight.stl</uri>
					</mesh>
				</geometry>
				<material>
					<script>
						<name>Gazebo/Grey</name>
					</script>
				</material>
			</visual>
			<sensor name='finger' type='contact'>
			  <contact>
			    <collision>collision</collision>
			  </contact>
			</sensor>
		</link>

		<joint name ="gripper_right_finger_joint" type="revolute">
			<parent>gripper_wrist</parent>
			<child>gripper_right_finger</child>
			<pose>0.1825 -0.02175 0 0 0 0</pose>
			<axis>
				<xyz>0 0 1</xyz>
				<limit>
					<upper>0.0</upper>
					<lower>-0.7854</lower>
				</limit>
				<dynamics>
				  <damping>0.3</damping>
				</dynamics>
			</axis>
		</joint>

		<link name="left_front_wheel">
			<pose>0.095 0.135 -0.03 0 0 0</pose>
			<inertial>
				<mass>0.5</mass>
				<inertia>
					<ixx>0.00635</ixx>
					<ixy>0.0</ixy>
					<ixz>0.0</ixz>
					<iyy>0.00635</iyy>
					<iyz>0.0</iyz>
					<izz>0.009</izz>
				</inertia>
			</inertial>
			<collision name="collision">
				<pose>0 0 0 1.5708 0 0</pose>
				<geometry>
					<cylinder>
						<radius>.0575</radius>
						<length>.07</length>
 					</cylinder>
				</geometry>
				<surface>
					<friction>
						<ode>
							<mu>0.8</mu>
							<mu2>0.7</mu2>
						</ode>
					</friction>
				</surface>
			</collision>
			<visual name="visual">
				<geometry>
					<mesh>
						<uri>model://swarmie/meshes/TireWheelLeft.stl</uri>
					</mesh>
				</geometry>
				<material>
					<script>
						<name>Gazebo/Grey</name>
					</script>
				</material>
			</visual>
		</link>

		<joint name="left_front" type="revolute">
			<parent>base_link</parent>
			<child>left_front_wheel</child>
			<axis>
				<xyz>0 1 0</xyz>
			</axis>
		</joint>

		<link name="right_front_wheel">
			<pose>0.095 -0.135 -0.03 0 0 0</pose>
			<inertial>
				<mass>0.5</mass>
				<inertia>
					<ixx>0.00635</ixx>
					<ixy>0.0</ixy>
					<ixz>0.0</ixz>
					<iyy>0.00635</iyy>
					<iyz>0.0</iyz>
					<izz>0.009</izz>
				</inertia>
			</inertial>
			<collision name="collision">
				<pose>0 0 0 -1.5708 0 0</pose>
				<geometry>
					<cylinder>
						<radius>.0575</radius>
						<length>.07</length>
					</cylinder>
				</geometry>
				<surface>
					<friction>
						<ode>
							<mu>0.8</mu>
							<mu2>0.7</mu2>
						</ode>
					</friction>
				</surface>
			</collision>
			<visual name="visual">
				<geometry>
					<mesh>
						<uri>model://swarmie/meshes/TireWheelRight.stl</uri>
					</mesh>
				</geometry>
				<material>
					<script>
						<name>Gazebo/Grey</name>
					</script>
				</material>
			</visual>
		</link>

		<joint name="right_front" type="revolute">
			<parent>base_link</parent>
			<child>right_front_wheel</child>
			<axis>
				<xyz>0 1 0</xyz>
			</axis>
		</joint>

		<link name="left_rear_wheel">
			<pose>-0.095 0.135 -0.03 0 0 0</pose>
			<inertial>
				<mass>0.5</mass>
				<inertia>
					<ixx>0.00635</ixx>
					<ixy>0.0</ixy>
					<ixz>0.0</ixz>
					<iyy>0.00635</iyy>
					<iyz>0.0</iyz>
					<izz>0.009</izz>
				</inertia>
			</inertial>
			<collision name="collision">
				<pose>0 0 0 1.5708 0 0</pose>
				<geometry>
					<cylinder>
						<radius>.0575</radius>
						<length>.065</length>
					</cylinder>
				</geometry>
				<surface>
					<friction>
						<ode>
							<mu>0.8</mu>
							<mu2>0.7</mu2>
						</ode>
					</friction>
				</surface>
			</collision>
			<visual name="visual">
				<geometry>
					<mesh>
						<uri>model://swarmie/meshes/TireWheelLeft.stl</uri>
					</mesh>
				</geometry>
				<material>
					<script>
						<name>Gazebo/Grey</name>
					</script>
				</material>
			</visual>
		</link>

		<joint name="left_rear" type="revolute">
			<parent>base_link</parent>
			<child>left_rear_wheel</child>
			<axis>
				<xyz>0 1 0</xyz>
			</axis>
		</joint>

		<link name="right_rear_wheel">
			<pose>-0.095 -0.135 -0.03 0 0 0</pose>
			<inertial>
				<mass>0.5</mass>
				<inertia>
					<ixx>0.00635</ixx>
					<ixy>0.0</ixy>
					<ixz>0.0</ixz>
					<iyy>0.00635</iyy>
					<iyz>0.0</iyz>
					<izz>0.009</izz>
				</inertia>
			</inertial>
			<collision name="collision">
				<pose>0 0 0 -1.5708 0 0</pose>
				<geometry>
					<cylinder>
						<radius>.0575</radius>
						<length>.07</length>
					</cylinder>
				</geometry>
				<surface>
					<friction>
						<ode>
							<mu>0.8</mu>
							<mu2>0.7</mu2>
						</ode>
					</friction>
				</surface>
			</collision>
			<visual name="visual">
				<geometry>
					<mesh>
						<uri>model://swarmie/meshes/TireWheelRight.stl</uri>
					</mesh>
				</geometry>
				<material>
					<script>
						<name>Gazebo/Grey</name>
					</script>
				</material>
			</visual>
		</link>

		<joint name="right_rear" type="revolute">
			<parent>base_link</parent>
			<child>right_rear_wheel</child>
			<axis>
				<xyz>0 1 0</xyz>
			</axis>
		</joint>   

		<joint name="us_center_joint" type="revolute">
			<parent>base_link</parent>
			<child>us_center_link</child>
			<axis>
				<xyz>0 0 1</xyz>
				<limit>
					<upper>0</upper>
					<lower>0</lower>
				</limit>
			</axis>
		</joint>

		<link name="us_center_link">
			<sensor type="ray" name="us_center_sensor">
				<pose>0.15 0 0.053 0 0 0</pose>
				<visualize>false</visualize>
				<update_rate>5</update_rate>
				<ray>
					<scan>
						<horizontal>
							<samples>3</samples>
							<resolution>1.0</resolution>
							<min_angle>-.478</min_angle>
							<max_angle>0.478</max_angle>
						</horizontal>
					</scan>
					<range>
						<min>0.010</min>
						<max>3</max>
						<resolution>0.01</resolution>
					</range>
				</ray>
				<plugin name="us" filename="libhector_gazebo_ros_sonar.so">
					<gaussianNoise>0.005</gaussianNoise>
					<topicName>/achilles/sonarCenter</topicName>
					<frameId>us_center_link</frameId>
				</plugin>
			</sensor>
		</link>

		<joint name="us_right_joint" type="revolute">
			<parent>base_link</parent>
			<child>us_right_link</child>
			<axis>
				<xyz>0 0 1</xyz>
				<limit>
					<upper>0</upper>
					<lower>0</lower>
				</limit>
			</axis>
		</joint>

		<link name="us_right_link">
			<sensor type="ray" name="us_right_sensor">
				<pose>0.15 -0.07 0.053 0.0 0.0 -0.43633</pose>
				<visualize>false</visualize>
				<update_rate>5</update_rate>
				<ray>
					<scan>
						<horizontal>
							<samples>3</samples>
							<resolution>1.0</resolution>
							<min_angle>-.478</min_angle>
							<max_angle>0.478</max_angle>
						</horizontal>
					</scan>
					<range>
						<min>0.010</min>
						<max>3</max>
						<resolution>0.01</resolution>
					</range>
				</ray>
				<plugin name="us" filename="libhector_gazebo_ros_sonar.so">
					<gaussianNoise>0.005</gaussianNoise>
					<topicName>/achilles/sonarRight</topicName>
					<frameId>us_center_link</frameId>
				</plugin>
			</sensor>
		</link>

		<joint name="us_left_joint" type="revolute">
			<parent>base_link</parent>
			<child>us_left_link</child>
			<axis>
				<xyz>0 0 1</xyz>
				<limit>
					<upper>0</upper>
					<lower>0</lower>
				</limit>
			</axis>
		</joint>

		<link name="us_left_link">
			<sensor type="ray" name="us_left_sensor">
				<pose>0.15 0.07 0.053 0.0 0.0 0.43633</pose>
				<visualize>false</visualize>
				<update_rate>5</update_rate>
				<ray>
					<scan>
						<horizontal>
							<samples>3</samples>
							<resolution>1.0</resolution>
							<min_angle>-.478</min_angle>
							<max_angle>0.478</max_angle>
						</horizontal>
					</scan>
					<range>
						<min>0.010</min>
						<max>3</max>
						<resolution>0.01</resolution>
					</range>
				</ray>
				<plugin name="us" filename="libhector_gazebo_ros_sonar.so">
					<gaussianNoise>0.005</gaussianNoise>
					<topicName>/achilles/sonarLeft</topicName>
					<frameId>us_center_link</frameId>
				</plugin>
			</sensor>
		</link>

		<joint name="camera_joint" type="revolute">
			<parent>base_link</parent>
			<child>camera_link</child>
			<axis>
				<xyz>0 1 0</xyz>
				<limit>
					<upper>0</upper>
					<lower>0</lower>
				</limit>
			</axis>
		</joint>

		<link name="camera_link">
			<inertial>
				<mass>0.2</mass>
				<inertia>
					<ixx>0.0001</ixx>
					<ixy>0.0</ixy>
					<ixz>0.0</ixz>
					<iyy>0.0001</iyy>
					<iyz>0.0</iyz>
					<izz>0.0002</izz>
				</inertia>
			</inertial>
			<sensor type="camera" name="camera">
				<pose>0.145 -0.0162 0.088 0.0 0.628 0.0</pose>
				<visualize>false</visualize>
				<update_rate>6.0</update_rate>
				<camera name="head">
					<horizontal_fov>1.0123</horizontal_fov>
					<image>
						<width>320</width>
						<height>240</height>
						<format>B8G8R8</format>
					</image>
					<clip>
						<near>0.02</near>
						<far>300</far>
					</clip>
					<noise>
						<type>gaussian</type>
						<mean>0.0</mean>
						<stddev>0.007</stddev>
					</noise>
				</camera>
				<plugin name="camera_controller" filename="libgazebo_ros_camera.so">
					<alwaysOn>true</alwaysOn>
					<updateRate>0.0</updateRate>
					<cameraName>/achilles/camera</cameraName>
					<imageTopicName>/achilles/camera/image</imageTopicName>
					<cameraInfoTopicName>/achilles/camera/info</cameraInfoTopicName>
					<frameName>camera_link</frameName>
					<hackBaseline>0.1</hackBaseline>
					<distortionK1>0.0</distortionK1>
					<distortionK2>0.0</distortionK2>
					<distortionK3>0.0</distortionK3>
					<distortionT1>0.0</distortionT1>
					<distortionT2>0.0</distortionT2>
					<CxPrime>0.0</CxPrime>
					<Cx>0.0</Cx>
					<Cy>0.0</Cy>
					<focalLength>0.0</focalLength>
				</plugin>
			</sensor>
		</link>

		<!-- Gripper plugin-->
		<plugin name="gripper_sim" filename="libgazebo_plugins_gripper.so">
			<!-- required: joint definitions -->
			<wristJoint>gripper_wrist_joint</wristJoint>
			<leftFingerJoint>gripper_left_finger_joint</leftFingerJoint>
			<rightFingerJoint>gripper_right_finger_joint</rightFingerJoint>

			<!-- required: data input topics for this plugin -->
			<wristTopic>/achilles/wristAngle/cmd</wristTopic>
			<fingerTopic>/achilles/fingerAngle/cmd</fingerTopic>

			<!-- optional: print debug info to the console -->
			<debug>
				<!-- true (debug mode is on) or false (debug mode is off) -->
				<printToConsole>false</printToConsole>
				<!-- time (in simulated seconds) between debug print statements -->
				<printDelayInSeconds>5.0</printDelayInSeconds>
			</debug>

			<!-- optional: the refresh rate of the gripper and all debugging output -->
			<!-- this value is the number of updates performed per second -->
			<!-- warning: low values (i.e. < 100) can cause the gripper to have poor performance -->
			<updateRate>1000.0</updateRate>

			<!-- optional: set the default PID values for the wrist joint -->
			<!-- values in order: Proportional gain, Integral gain, Derivative gain -->
			<wristPID>2.5 0.0 0.0</wristPID>

			<!-- optional: set the default PID values for the finger joints -->
			<!-- values in order: Proportional gain, Integral gain, Derivative gain -->
			<!-- it is always assumed that both fingers use the same PID values -->
			<fingerPID>2.5 0.0 0.0</fingerPID>

			<!-- optional: set the min/max force applicable to the wrist joint in Newtons -->
			<!-- values in order: minimum force, maximum force -->
			<wristForceLimits>-10 10</wristForceLimits>

			<!-- optional: set the min/max force applicable to the finger joints in Newtons -->
			<!-- values in order: minimum force, maximum force -->
			<!-- it is always assumed that both fingers use the same min/max force values -->
			<fingerForceLimits>-10 10</fingerForceLimits>
		</plugin>

		<!-- Skid Steer Drive plugin -->
		<plugin name="skid_steer_drive_controller" filename="libgazebo_ros_skid_steer_drive.so">
			<updateRate>10</updateRate>
			<robotNamespace>/</robotNamespace>
			<leftFrontJoint>left_front</leftFrontJoint>
			<rightFrontJoint>right_front</rightFrontJoint>
			<leftRearJoint>left_rear</leftRearJoint>
			<rightRearJoint>right_rear</rightRearJoint>
			<wheelSeparation>0.27</wheelSeparation>
			<wheelDiameter>0.12</wheelDiameter>
			<robotBaseFrame>achilles/base_link</robotBaseFrame>
			<torque>2.8</torque>
			<commandTopic>/achilles/skidsteer</commandTopic>
			<odometryTopic>/achilles/odom</odometryTopic>
			<odometryFrame>achilles/odom</odometryFrame>
			<broadcastTF>0</broadcastTF>
		</plugin>

		<!-- GPS plugin -->
		<plugin name="gps_sim" filename="libhector_gazebo_ros_gps.so">
			<alwaysOn>1</alwaysOn>
			<updateRate>5</updateRate>
			<bodyName>base_link</bodyName>
			<frameId>achilles/base_link</frameId>
			<topicName>/achilles/fix</topicName>
			<referenceLatitude>28.584810</referenceLatitude>
			<referenceLongitude>-80.649650</referenceLongitude>
			<referenceHeading>0.0</referenceHeading>
			<referenceAltitude>10.0</referenceAltitude>
			<offset>0.0 0.0 0.0</offset>
			<drift>0.1 0.1 0</drift>
			<driftFrequency>0.0 0.0 0.0</driftFrequency>
			<gaussianNoise>0.4 0.5 0.0</gaussianNoise>
		</plugin>

		<!-- IMU plugin -->
		<plugin name="imu_sim" filename="libhector_gazebo_ros_imu.so">
			<updateRate>10</updateRate>
			<bodyName>base_link</bodyName>
			<frameId>achilles/base_link</frameId>
			<topicName>/achilles/imu</topicName>
			<xyzOffset>0 0 0</xyzOffset>
			<rpyOffset>0 0 0</rpyOffset>
			<gaussianNoise>0</gaussianNoise>  
			<accelDrift>0.5 0.5 0.5</accelDrift>
			<accelGaussianNoise>0.35 0.35 0.3</accelGaussianNoise>
			<rateDrift>0.1 0.1 0.1</rateDrift>
			<rateGaussianNoise>0.05 0.05 0.015</rateGaussianNoise>
			<headingDrift>0.01</headingDrift>
			<headingGaussianNoise>0.01</headingGaussianNoise>
		</plugin>

	</model>
</sdf>
