<?xml version="1.0" encoding="utf-8"?>
<sdf version='1.4'>

    <model name="paris">
        <static>false</static>

        <link name='base_link'>
            <pose>0 0 .080 0 0 0</pose>
	      <inertial>
		<mass>15</mass>
		<inertia>
		  <ixx>3.0</ixx>
		  <ixy>0.0</ixy>
		  <ixz>0.0</ixz>
		  <iyy>5.0</iyy>
		  <iyz>0.0</iyz>
		  <izz>0.3</izz>
		</inertia>
	      </inertial>
            <collision name='collision'>
                <geometry>
                    <box>
                        <size>.308 .180 .136</size>
                    </box>
                </geometry>
            </collision>
            <visual name='visual'>
            <pose>0 0 -0.037 0 0 0</pose>
                <geometry>
                    <!-- <box>
                        <size>.308 .180 .136</size>
                    </box> -->
                    <mesh>
                        <uri>model://paris/meshes/Swarmie_Chassis_V2.dae</uri>
                    </mesh>
                </geometry>
                <material>
                    <script>
                        <name>Gazebo/FlatBlack</name>
                    </script>
                </material>
            </visual>
        </link>
        
        <link name='top'>
            <pose>0 0 .180 0 0 0</pose>
	      <inertial>
		<mass>1</mass>
		<inertia>
		  <ixx>0.3</ixx>
		  <ixy>0.0</ixy>
		  <ixz>0.0</ixz>
		  <iyy>0.5</iyy>
		  <iyz>0.0</iyz>
		  <izz>0.03</izz>
		</inertia>
	      </inertial>
            <collision name='collision'>
                <geometry>
                    <box>
                        <size>.209 .298 .001</size>
                    </box>
                </geometry>
            </collision>
            <visual name='visual'>
                <geometry>
                    <!-- <box>
                        <size>.209 .298 .001</size>
                    </box> -->
                    <mesh>
                        <uri>model://paris/meshes/Swarmie_Top_V2.dae</uri>
                    </mesh>
                </geometry>
                <material>
                    <script>
                        <name>Gazebo/Red</name>
                    </script>
                </material>
            </visual>
        </link>
        
        <joint name="top" type="revolute">
            <parent>base_link</parent>
            <child>top</child>
            <axis>
                <xyz>0 0 0</xyz>
                <limit>
                    <upper>0</upper>
                    <lower>0</lower>
                </limit>
            </axis>
        </joint>

        <link name="left_front_wheel">
            <pose>0.094 0.1295 0.06 1.5708 0 0</pose>
	    <inertial>
		<mass>2</mass>
		<inertia>
		  <ixx>0.005</ixx>
		  <ixy>0.0</ixy>
		  <ixz>0.0</ixz>
		  <iyy>0.005</iyy>
		  <iyz>0.0</iyz>
		  <izz>0.009</izz>
		</inertia>
	    </inertial>
            <collision name="collision">
                <geometry>
                    <cylinder>
                        <radius>.06</radius>
                        <length>.067</length>
                    </cylinder>
                </geometry>
		<surface>
		  <friction>
		    <ode>
		      <mu>0.8</mu>
		      <mu2>0.7</mu2>
		      <fdir1>0 0 0</fdir1>
		      <slip1>0.8</slip1>
		      <slip2>0.7</slip2>
		    </ode>
		  </friction>
		</surface>
            </collision>
            <visual name="visual">
                <geometry>
                    <!-- <cylinder>
                        <radius>.06</radius>
                        <length>.064</length>
                    </cylinder> -->
                    <mesh>
                        <uri>model://paris/meshes/Swarmie_Tire_V2.dae</uri>
                    </mesh>
                </geometry>
                <material>
                    <script>
                        <name>Gazebo/Grey</name>
                    </script>
                </material>
            </visual>
        </link>
        
        <joint name="left_front" type="revolute">
            <parent>base_link</parent>
            <child>left_front_wheel</child>
            <axis>
                <xyz>0 1 0</xyz>
            </axis>
        </joint>

        <link name="right_front_wheel">
            <pose>0.094 -0.1295 0.06 1.5708 0 0</pose>
	    <inertial>
		<mass>2</mass>
		<inertia>
		  <ixx>0.005</ixx>
		  <ixy>0.0</ixy>
		  <ixz>0.0</ixz>
		  <iyy>0.005</iyy>
		  <iyz>0.0</iyz>
		  <izz>0.009</izz>
		</inertia>
	    </inertial>
            <collision name="collision">
                <geometry>
                    <cylinder>
                        <radius>.06</radius>
                        <length>.067</length>
                    </cylinder>
                </geometry>
		<surface>
		  <friction>
		    <ode>
		      <mu>0.8</mu>
		      <mu2>0.7</mu2>
		      <fdir1>0 0 0</fdir1>
		      <slip1>0.8</slip1>
		      <slip2>0.7</slip2>
		    </ode>
		  </friction>
		</surface>
            </collision>
            <visual name="visual">
                <geometry>
                    <!-- <cylinder>
                        <radius>.06</radius>
                        <length>.064</length>
                    </cylinder> -->
                    <mesh>
                        <uri>model://paris/meshes/Swarmie_Tire_V2.dae</uri>
                    </mesh>
                </geometry>
                <material>
                    <script>
                        <name>Gazebo/Grey</name>
                    </script>
                </material>
            </visual>
        </link>
        
        <joint name="right_front" type="revolute">
            <parent>base_link</parent>
            <child>right_front_wheel</child>
            <axis>
                <xyz>0 1 0</xyz>
            </axis>
        </joint>

        <link name="left_rear_wheel">
            <pose>-0.094 0.1295 0.06 1.5708 0 0</pose>
	    <inertial>
		<mass>2</mass>
		<inertia>
		  <ixx>0.005</ixx>
		  <ixy>0.0</ixy>
		  <ixz>0.0</ixz>
		  <iyy>0.005</iyy>
		  <iyz>0.0</iyz>
		  <izz>0.009</izz>
		</inertia>
	    </inertial>
            <collision name="collision">
                <geometry>
                    <cylinder>
                        <radius>.06</radius>
                        <length>.067</length>
                    </cylinder>
                </geometry>
		<surface>
		  <friction>
		    <ode>
		      <mu>0.8</mu>
		      <mu2>0.7</mu2>
		      <fdir1>0 0 0</fdir1>
		      <slip1>0.8</slip1>
		      <slip2>0.7</slip2>
		    </ode>
		  </friction>
		</surface>
            </collision>
            <visual name="visual">
                <geometry>
                    <!-- <cylinder>
                        <radius>.06</radius>
                        <length>.064</length>
                    </cylinder> -->
                    <mesh>
                        <uri>model://paris/meshes/Swarmie_Tire_V2.dae</uri>
                    </mesh>
                </geometry>
                <material>
                    <script>
                        <name>Gazebo/Grey</name>
                    </script>
                </material>
            </visual>
        </link>
        
        <joint name="left_rear" type="revolute">
            <parent>base_link</parent>
            <child>left_rear_wheel</child>
            <axis>
                <xyz>0 1 0</xyz>
            </axis>
        </joint>

        <link name="right_rear_wheel">
            <pose>-0.094 -0.1295 0.06 1.5708 0 0</pose>
	    <inertial>
		<mass>2</mass>
		<inertia>
		  <ixx>0.005</ixx>
		  <ixy>0.0</ixy>
		  <ixz>0.0</ixz>
		  <iyy>0.005</iyy>
		  <iyz>0.0</iyz>
		  <izz>0.009</izz>
		</inertia>
	    </inertial>
            <collision name="collision">
                <geometry>
                    <cylinder>
                        <radius>.06</radius>
                        <length>.067</length>
                    </cylinder>
                </geometry>
		<surface>
		  <friction>
		    <ode>
		      <mu>0.8</mu>
		      <mu2>0.7</mu2>
		      <fdir1>0 0 0</fdir1>
		      <slip1>0.8</slip1>
		      <slip2>0.7</slip2>
		    </ode>
		  </friction>
		</surface>
            </collision>
            <visual name="visual">
                <geometry>
                    <!-- <cylinder>
                        <radius>.06</radius>
                        <length>.064</length>
                    </cylinder> -->
                    <mesh>
                        <uri>model://paris/meshes/Swarmie_Tire_V2.dae</uri>
                    </mesh>
                </geometry>
                <material>
                    <script>
                        <name>Gazebo/Grey</name>
                    </script>
                </material>
            </visual>
        </link>
        
        <joint name="right_rear" type="revolute">
            <parent>base_link</parent>
            <child>right_rear_wheel</child>
            <axis>
                <xyz>0 1 0</xyz>
            </axis>
        </joint>   

        <joint name="us_center_joint" type="revolute">
            <parent>base_link</parent>
            <child>us_center_link</child>
            <axis>
                <xyz>0 0 1</xyz>
                <limit>
                    <upper>0</upper>
                    <lower>0</lower>
                </limit>
            </axis>
        </joint>

        <link name="us_center_link">
            <visual name='visual'>
                <pose>0.11 0 .122 0 0 -1.5708</pose>
                <geometry>
                    <mesh>
                        <uri>model://paris/meshes/SwarmieUS_V2.dae</uri>
                    </mesh>
                </geometry>
                <material>
                    <script>
                        <name>Gazebo/Green</name>
                    </script>
                </material>
            </visual>

            <sensor type="ray" name="us_center_sensor">
                <pose>.165 0 .122 0 0 0</pose>
                <visualize>false</visualize>
                <update_rate>5</update_rate>
                <ray>
                    <scan>
                        <horizontal>
                            <samples>3</samples>
                            <resolution>1.0</resolution>
                            <min_angle>-.478</min_angle>
                            <max_angle>0.478</max_angle>
                        </horizontal>
                    </scan>
                    <range>
                        <min>0.010</min>
                        <max>3</max>
                        <resolution>0.01</resolution>
                    </range>
                </ray>
                <plugin name="us" filename="libhector_gazebo_ros_sonar.so">
                    <gaussianNoise>0.005</gaussianNoise>
                    <topicName>/paris/sonarCenter</topicName>
                    <frameId>us_center_link</frameId>
                </plugin>
            </sensor>
        </link> 
              
        <joint name="us_right_joint" type="revolute">
            <parent>base_link</parent>
            <child>us_right_link</child>
            <axis>
                <xyz>0 0 1</xyz>
                <limit>
                    <upper>0</upper>
                    <lower>0</lower>
                </limit>
            </axis>
        </joint>
               
        <link name="us_right_link">
            <visual name='visual'>
                <pose>0.1 -.048 .122 0 0 -2.0071</pose>
                <geometry>
                    <mesh>
                        <uri>model://paris/meshes/SwarmieUS_V2.dae</uri>
                    </mesh>
                </geometry>
                <material>
                    <script>
                        <name>Gazebo/Green</name>
                    </script>
                </material>
            </visual>

            <sensor type="ray" name="us_right_sensor">
                <pose>0.16 -.055 .122 0 0 -.43633</pose>
                <visualize>false</visualize>
                <update_rate>5</update_rate>
                <ray>
                    <scan>
                        <horizontal>
                            <samples>3</samples>
                            <resolution>1.0</resolution>
                            <min_angle>-.478</min_angle>
                            <max_angle>0.478</max_angle>
                        </horizontal>
                    </scan>
                    <range>
                        <min>0.010</min>
                        <max>3</max>
                        <resolution>0.01</resolution>
                    </range>
                </ray>
                <plugin name="us" filename="libhector_gazebo_ros_sonar.so">
                    <gaussianNoise>0.005</gaussianNoise>
                    <topicName>/paris/sonarRight</topicName>
                    <frameId>us_center_link</frameId>
                </plugin>
            </sensor>
        </link> 
               
        <joint name="us_left_joint" type="revolute">
            <parent>base_link</parent>
            <child>us_left_link</child>
            <axis>
                <xyz>0 0 1</xyz>
                <limit>
                    <upper>0</upper>
                    <lower>0</lower>
                </limit>
            </axis>
        </joint>
        
        <link name="us_left_link">
            <visual name='visual'>
                <pose>0.1 0.048 .122 0 0 -1.1345</pose>
                <geometry>
                    <mesh>
                        <uri>model://paris/meshes/SwarmieUS_V2.dae</uri>
                    </mesh>
                </geometry>
                <material>
                    <script>
                        <name>Gazebo/Green</name>
                    </script>
                </material>
            </visual>

            <sensor type="ray" name="us_left_sensor">
                <pose>.16 .055 .122 0 0 .43633</pose>
                <visualize>false</visualize>
                <update_rate>5</update_rate>
                <ray>
                    <scan>
                        <horizontal>
                            <samples>3</samples>
                            <resolution>1.0</resolution>
                            <min_angle>-.478</min_angle>
                            <max_angle>0.478</max_angle>
                        </horizontal>
                    </scan>
                    <range>
                        <min>0.010</min>
                        <max>3</max>
                        <resolution>0.01</resolution>
                    </range>
                </ray>
                <plugin name="us" filename="libhector_gazebo_ros_sonar.so">
                    <gaussianNoise>0.005</gaussianNoise>
                    <topicName>/paris/sonarLeft</topicName>
                    <frameId>us_center_link</frameId>
                </plugin>
            </sensor>
        </link>
        
	<joint name="camera_joint" type="revolute">
            <parent>base_link</parent>
            <child>camera_link</child>
            <axis>
                <xyz>0 1 0</xyz>
                <limit>
                    <upper>0</upper>
                    <lower>0</lower>
                </limit>
            </axis>
        </joint>

        <link name="camera_link">
            <visual name='visual'>
                <pose>0.072 0 .185 0 0 1.5708</pose>
                <geometry>
                    <mesh>
                        <uri>model://paris/meshes/Swarmie_Camera_V2.dae</uri>
                    </mesh>
                </geometry>
                <material>
                    <script>
                        <name>Gazebo/Grey</name>
                    </script>
                </material>
            </visual>
	      <inertial>
		<mass>1</mass>
		<inertia>
		  <ixx>0.3</ixx>
		  <ixy>0.0</ixy>
		  <ixz>0.0</ixz>
		  <iyy>0.5</iyy>
		  <iyz>0.0</iyz>
		  <izz>0.03</izz>
		</inertia>
	      </inertial>
	    

            <sensor type="camera" name="camera">
                <pose>0.089 -0.01 0.236 0 0.436 0</pose>
                <update_rate>6.0</update_rate>
                <camera name="head">
                    <horizontal_fov>1.0123</horizontal_fov>
                    <image>
                        <width>640</width>
                        <height>320</height>
                        <format>B8G8R8</format>
                    </image>
                    <clip>
                        <near>0.02</near>
                        <far>300</far>
                    </clip>
                    <noise>
                        <type>gaussian</type>
                        <!-- Noise is sampled independently per pixel on each frame.  
                        That pixel's noise value is added to each of its color
                        channels, which at that point lie in the range [0,1]. -->
                        <mean>0.0</mean>
                        <stddev>0.007</stddev>
                    </noise>
                </camera>
                <plugin name="camera_controller" filename="libgazebo_ros_camera.so">
                    <alwaysOn>true</alwaysOn>
                    <updateRate>0.0</updateRate>
                    <cameraName>/paris/camera</cameraName>
                    <imageTopicName>/paris/camera/image</imageTopicName>
                    <cameraInfoTopicName>/paris/camera/info</cameraInfoTopicName>
                    <frameName>camera_link</frameName>
                    <hackBaseline>0.1</hackBaseline>
                    <distortionK1>.0</distortionK1>
                    <distortionK2>0.0</distortionK2>
                    <distortionK3>0.0</distortionK3>
                    <distortionT1>0.0</distortionT1>
                    <distortionT2>0.0</distortionT2>
                </plugin>
            </sensor>
        </link>

        <plugin name="skid_steer_drive_controller" filename="libgazebo_ros_skid_steer_drive.so">
            <updateRate>10</updateRate>
            <robotNamespace>/</robotNamespace>
            <leftFrontJoint>left_front</leftFrontJoint>
            <rightFrontJoint>right_front</rightFrontJoint>
            <leftRearJoint>left_rear</leftRearJoint>
            <rightRearJoint>right_rear</rightRearJoint>
            <wheelSeparation>0.187</wheelSeparation>
            <wheelDiameter>0.120</wheelDiameter>
            <robotBaseFrame>base_link</robotBaseFrame>
            <torque>2.8</torque>
            <commandTopic>/paris/velocity</commandTopic>
            <odometryTopic>/paris/odom</odometryTopic>
            <odometryFrame>odom</odometryFrame>
        </plugin>
        
        <!-- start GPS plugin -->
        <plugin name="gps_sim" filename="libhector_gazebo_ros_gps.so">
            <alwaysOn>1</alwaysOn>
            <updateRate>5</updateRate>
            <bodyName>base_link</bodyName>
            <topicName>/paris/fix</topicName>
            <!--<velocityTopicName>/paris/fix_velocity</velocityTopicName>-->
            <referenceLatitude>28.584810</referenceLatitude>
            <referenceLongitude>-80.649650</referenceLongitude>
            <referenceHeading>0.0</referenceHeading>
            <referenceAltitude>10.0</referenceAltitude>
            <offset>0.0 0.0 0.0</offset>
            <drift>0.1 0.1 0</drift>
            <driftFrequency>0.0 0.0 0.0</driftFrequency>
            <gaussianNoise>0.4 0.5 0.0</gaussianNoise>
            <!--<velocityOffset>0.0 0.0 0.0</velocityOffset>
            <velocityDrift>0 0 0</velocityDrift>
            <velocityDriftFrequency>0.0 0.0 0.0</velocityDriftFrequency>
            <velocityGaussianNoise>0.1 0.1 0.1</velocityGaussianNoise>-->
        </plugin>
        <!-- end GPS plugin -->

        <!-- start IMU plugin -->
        <plugin name="imu_sim" filename="libhector_gazebo_ros_imu.so">
            <updateRate>10</updateRate>
            <bodyName>base_link</bodyName>
            <topicName>/paris/imu</topicName>
            <rpyOffsets>0 0 0</rpyOffsets> 
            <gaussianNoise>0</gaussianNoise>  
            <accelDrift>0.5 0.5 0.5</accelDrift>
            <accelGaussianNoise>0.35 0.35 0.3</accelGaussianNoise>
            <rateDrift>0.1 0.1 0.1</rateDrift>
            <rateGaussianNoise>0.05 0.05 0.015</rateGaussianNoise>
            <headingDrift>0.01</headingDrift>
            <headingGaussianNoise>0.01</headingGaussianNoise>
        </plugin>
        <!-- end IMU plugin -->
      
    </model>

</sdf>
